2025-03-24 20:00:04,997 - root - ERROR - Failed to initialize model: Could not load model distilbert-base-uncased-finetuned-sst-2-english with any of the following classes: (<class 'transformers.models.auto.modeling_auto.AutoModelForSequenceClassification'>,). See the original errors:

while loading with AutoModelForSequenceClassification, an error is thrown:
Traceback (most recent call last):
  File "c:\Users\jordi\Documents\UNI\backend-jbl42\.venv\Lib\site-packages\urllib3\connectionpool.py", line 464, in _make_request
    self._validate_conn(conn)
    ~~~~~~~~~~~~~~~~~~~^^^^^^
  File "c:\Users\jordi\Documents\UNI\backend-jbl42\.venv\Lib\site-packages\urllib3\connectionpool.py", line 1093, in _validate_conn
    conn.connect()
    ~~~~~~~~~~~~^^
  File "c:\Users\jordi\Documents\UNI\backend-jbl42\.venv\Lib\site-packages\urllib3\connection.py", line 741, in connect
    sock_and_verified = _ssl_wrap_socket_and_match_hostname(
        sock=sock,
    ...<14 lines>...
        assert_fingerprint=self.assert_fingerprint,
    )
  File "c:\Users\jordi\Documents\UNI\backend-jbl42\.venv\Lib\site-packages\urllib3\connection.py", line 920, in _ssl_wrap_socket_and_match_hostname
    ssl_sock = ssl_wrap_socket(
        sock=sock,
    ...<8 lines>...
        tls_in_tls=tls_in_tls,
    )
  File "c:\Users\jordi\Documents\UNI\backend-jbl42\.venv\Lib\site-packages\urllib3\util\ssl_.py", line 460, in ssl_wrap_socket
    ssl_sock = _ssl_wrap_socket_impl(sock, context, tls_in_tls, server_hostname)
  File "c:\Users\jordi\Documents\UNI\backend-jbl42\.venv\Lib\site-packages\urllib3\util\ssl_.py", line 504, in _ssl_wrap_socket_impl
    return ssl_context.wrap_socket(sock, server_hostname=server_hostname)
           ~~~~~~~~~~~~~~~~~~~~~~~^^^^^^^^^^^^^^^^^^^^^^^^^^^^^^^^^^^^^^^
  File "C:\Program Files\WindowsApps\PythonSoftwareFoundation.Python.3.13_3.13.752.0_x64__qbz5n2kfra8p0\Lib\ssl.py", line 455, in wrap_socket
    return self.sslsocket_class._create(
           ~~~~~~~~~~~~~~~~~~~~~~~~~~~~^
        sock=sock,
        ^^^^^^^^^^
    ...<5 lines>...
        session=session
        ^^^^^^^^^^^^^^^
    )
    ^
  File "C:\Program Files\WindowsApps\PythonSoftwareFoundation.Python.3.13_3.13.752.0_x64__qbz5n2kfra8p0\Lib\ssl.py", line 1076, in _create
    self.do_handshake()
    ~~~~~~~~~~~~~~~~~^^
  File "C:\Program Files\WindowsApps\PythonSoftwareFoundation.Python.3.13_3.13.752.0_x64__qbz5n2kfra8p0\Lib\ssl.py", line 1372, in do_handshake
    self._sslobj.do_handshake()
    ~~~~~~~~~~~~~~~~~~~~~~~~~^^
ssl.SSLError: [SSL: WRONG_VERSION_NUMBER] wrong version number (_ssl.c:1028)

During handling of the above exception, another exception occurred:

Traceback (most recent call last):
  File "c:\Users\jordi\Documents\UNI\backend-jbl42\.venv\Lib\site-packages\urllib3\connectionpool.py", line 787, in urlopen
    response = self._make_request(
        conn,
    ...<10 lines>...
        **response_kw,
    )
  File "c:\Users\jordi\Documents\UNI\backend-jbl42\.venv\Lib\site-packages\urllib3\connectionpool.py", line 488, in _make_request
    raise new_e
urllib3.exceptions.SSLError: [SSL: WRONG_VERSION_NUMBER] wrong version number (_ssl.c:1028)

The above exception was the direct cause of the following exception:

Traceback (most recent call last):
  File "c:\Users\jordi\Documents\UNI\backend-jbl42\.venv\Lib\site-packages\requests\adapters.py", line 667, in send
    resp = conn.urlopen(
        method=request.method,
    ...<9 lines>...
        chunked=chunked,
    )
  File "c:\Users\jordi\Documents\UNI\backend-jbl42\.venv\Lib\site-packages\urllib3\connectionpool.py", line 841, in urlopen
    retries = retries.increment(
        method, url, error=new_e, _pool=self, _stacktrace=sys.exc_info()[2]
    )
  File "c:\Users\jordi\Documents\UNI\backend-jbl42\.venv\Lib\site-packages\urllib3\util\retry.py", line 519, in increment
    raise MaxRetryError(_pool, url, reason) from reason  # type: ignore[arg-type]
    ^^^^^^^^^^^^^^^^^^^^^^^^^^^^^^^^^^^^^^^^^^^^^^^^^^^
urllib3.exceptions.MaxRetryError: HTTPSConnectionPool(host='huggingface.co', port=443): Max retries exceeded with url: /distilbert-base-uncased-finetuned-sst-2-english/resolve/main/tf_model.h5 (Caused by SSLError(SSLError(1, '[SSL: WRONG_VERSION_NUMBER] wrong version number (_ssl.c:1028)')))

During handling of the above exception, another exception occurred:

Traceback (most recent call last):
  File "c:\Users\jordi\Documents\UNI\backend-jbl42\.venv\Lib\site-packages\transformers\pipelines\base.py", line 291, in infer_framework_load_model
    model = model_class.from_pretrained(model, **kwargs)
  File "c:\Users\jordi\Documents\UNI\backend-jbl42\.venv\Lib\site-packages\transformers\models\auto\auto_factory.py", line 573, in from_pretrained
    return model_class.from_pretrained(
           ~~~~~~~~~~~~~~~~~~~~~~~~~~~^
        pretrained_model_name_or_path, *model_args, config=config, **hub_kwargs, **kwargs
        ^^^^^^^^^^^^^^^^^^^^^^^^^^^^^^^^^^^^^^^^^^^^^^^^^^^^^^^^^^^^^^^^^^^^^^^^^^^^^^^^^
    )
    ^
  File "c:\Users\jordi\Documents\UNI\backend-jbl42\.venv\Lib\site-packages\transformers\modeling_utils.py", line 272, in _wrapper
    return func(*args, **kwargs)
  File "c:\Users\jordi\Documents\UNI\backend-jbl42\.venv\Lib\site-packages\transformers\modeling_utils.py", line 4317, in from_pretrained
    checkpoint_files, sharded_metadata = _get_resolved_checkpoint_files(
                                         ~~~~~~~~~~~~~~~~~~~~~~~~~~~~~~^
        pretrained_model_name_or_path=pretrained_model_name_or_path,
        ^^^^^^^^^^^^^^^^^^^^^^^^^^^^^^^^^^^^^^^^^^^^^^^^^^^^^^^^^^^^
    ...<13 lines>...
        commit_hash=commit_hash,
        ^^^^^^^^^^^^^^^^^^^^^^^^
    )
    ^
  File "c:\Users\jordi\Documents\UNI\backend-jbl42\.venv\Lib\site-packages\transformers\modeling_utils.py", line 1109, in _get_resolved_checkpoint_files
    if has_file(pretrained_model_name_or_path, TF2_WEIGHTS_NAME, **has_file_kwargs):
       ~~~~~~~~^^^^^^^^^^^^^^^^^^^^^^^^^^^^^^^^^^^^^^^^^^^^^^^^^^^^^^^^^^^^^^^^^^^^
  File "c:\Users\jordi\Documents\UNI\backend-jbl42\.venv\Lib\site-packages\transformers\utils\hub.py", line 686, in has_file
    response = get_session().head(
        hf_hub_url(path_or_repo, filename=filename, revision=revision, repo_type=repo_type),
    ...<3 lines>...
        timeout=10,
    )
  File "c:\Users\jordi\Documents\UNI\backend-jbl42\.venv\Lib\site-packages\requests\sessions.py", line 624, in head
    return self.request("HEAD", url, **kwargs)
           ~~~~~~~~~~~~^^^^^^^^^^^^^^^^^^^^^^^
  File "c:\Users\jordi\Documents\UNI\backend-jbl42\.venv\Lib\site-packages\requests\sessions.py", line 589, in request
    resp = self.send(prep, **send_kwargs)
  File "c:\Users\jordi\Documents\UNI\backend-jbl42\.venv\Lib\site-packages\requests\sessions.py", line 703, in send
    r = adapter.send(request, **kwargs)
  File "c:\Users\jordi\Documents\UNI\backend-jbl42\.venv\Lib\site-packages\huggingface_hub\utils\_http.py", line 96, in send
    return super().send(request, *args, **kwargs)
           ~~~~~~~~~~~~^^^^^^^^^^^^^^^^^^^^^^^^^^
  File "c:\Users\jordi\Documents\UNI\backend-jbl42\.venv\Lib\site-packages\requests\adapters.py", line 698, in send
    raise SSLError(e, request=request)
requests.exceptions.SSLError: (MaxRetryError("HTTPSConnectionPool(host='huggingface.co', port=443): Max retries exceeded with url: /distilbert-base-uncased-finetuned-sst-2-english/resolve/main/tf_model.h5 (Caused by SSLError(SSLError(1, '[SSL: WRONG_VERSION_NUMBER] wrong version number (_ssl.c:1028)')))"), '(Request ID: 6850e52b-5e2a-407e-acd8-e88b50cabb82)')



2025-03-24 19:02:57,018 - root - ERROR - Failed to initialize model: Could not load model distilbert-base-uncased-finetuned-sst-2-english with any of the following classes: (<class 'transformers.models.auto.modeling_auto.AutoModelForSequenceClassification'>,). See the original errors:

while loading with AutoModelForSequenceClassification, an error is thrown:
Traceback (most recent call last):
  File "/usr/local/lib/python3.12/site-packages/urllib3/connectionpool.py", line 464, in _make_request
    self._validate_conn(conn)
  File "/usr/local/lib/python3.12/site-packages/urllib3/connectionpool.py", line 1093, in _validate_conn
    conn.connect()
  File "/usr/local/lib/python3.12/site-packages/urllib3/connection.py", line 741, in connect
    sock_and_verified = _ssl_wrap_socket_and_match_hostname(
                        ^^^^^^^^^^^^^^^^^^^^^^^^^^^^^^^^^^^^
  File "/usr/local/lib/python3.12/site-packages/urllib3/connection.py", line 920, in _ssl_wrap_socket_and_match_hostname
    ssl_sock = ssl_wrap_socket(
               ^^^^^^^^^^^^^^^^
  File "/usr/local/lib/python3.12/site-packages/urllib3/util/ssl_.py", line 460, in ssl_wrap_socket
    ssl_sock = _ssl_wrap_socket_impl(sock, context, tls_in_tls, server_hostname)
               ^^^^^^^^^^^^^^^^^^^^^^^^^^^^^^^^^^^^^^^^^^^^^^^^^^^^^^^^^^^^^^^^^
  File "/usr/local/lib/python3.12/site-packages/urllib3/util/ssl_.py", line 504, in _ssl_wrap_socket_impl
    return ssl_context.wrap_socket(sock, server_hostname=server_hostname)
           ^^^^^^^^^^^^^^^^^^^^^^^^^^^^^^^^^^^^^^^^^^^^^^^^^^^^^^^^^^^^^^
  File "/usr/local/lib/python3.12/ssl.py", line 455, in wrap_socket
    return self.sslsocket_class._create(
           ^^^^^^^^^^^^^^^^^^^^^^^^^^^^^
  File "/usr/local/lib/python3.12/ssl.py", line 1041, in _create
    self.do_handshake()
  File "/usr/local/lib/python3.12/ssl.py", line 1319, in do_handshake
    self._sslobj.do_handshake()
ssl.SSLError: [SSL: WRONG_VERSION_NUMBER] wrong version number (_ssl.c:1010)

During handling of the above exception, another exception occurred:

Traceback (most recent call last):
  File "/usr/local/lib/python3.12/site-packages/urllib3/connectionpool.py", line 787, in urlopen
    response = self._make_request(
               ^^^^^^^^^^^^^^^^^^^
  File "/usr/local/lib/python3.12/site-packages/urllib3/connectionpool.py", line 488, in _make_request
    raise new_e
urllib3.exceptions.SSLError: [SSL: WRONG_VERSION_NUMBER] wrong version number (_ssl.c:1010)

The above exception was the direct cause of the following exception:

Traceback (most recent call last):
  File "/usr/local/lib/python3.12/site-packages/requests/adapters.py", line 667, in send
    resp = conn.urlopen(
           ^^^^^^^^^^^^^
  File "/usr/local/lib/python3.12/site-packages/urllib3/connectionpool.py", line 841, in urlopen
    retries = retries.increment(
              ^^^^^^^^^^^^^^^^^^
  File "/usr/local/lib/python3.12/site-packages/urllib3/util/retry.py", line 519, in increment
    raise MaxRetryError(_pool, url, reason) from reason  # type: ignore[arg-type]
    ^^^^^^^^^^^^^^^^^^^^^^^^^^^^^^^^^^^^^^^^^^^^^^^^^^^
urllib3.exceptions.MaxRetryError: HTTPSConnectionPool(host='huggingface.co', port=443): Max retries exceeded with url: /distilbert-base-uncased-finetuned-sst-2-english/resolve/main/tf_model.h5 (Caused by SSLError(SSLError(1, '[SSL: WRONG_VERSION_NUMBER] wrong version number (_ssl.c:1010)')))

During handling of the above exception, another exception occurred:

Traceback (most recent call last):
  File "/usr/local/lib/python3.12/site-packages/transformers/pipelines/base.py", line 291, in infer_framework_load_model
    model = model_class.from_pretrained(model, **kwargs)
            ^^^^^^^^^^^^^^^^^^^^^^^^^^^^^^^^^^^^^^^^^^^^
  File "/usr/local/lib/python3.12/site-packages/transformers/models/auto/auto_factory.py", line 573, in from_pretrained
    return model_class.from_pretrained(
           ^^^^^^^^^^^^^^^^^^^^^^^^^^^^
  File "/usr/local/lib/python3.12/site-packages/transformers/modeling_utils.py", line 272, in _wrapper
    return func(*args, **kwargs)
           ^^^^^^^^^^^^^^^^^^^^^
  File "/usr/local/lib/python3.12/site-packages/transformers/modeling_utils.py", line 4317, in from_pretrained
    checkpoint_files, sharded_metadata = _get_resolved_checkpoint_files(
                                         ^^^^^^^^^^^^^^^^^^^^^^^^^^^^^^^
  File "/usr/local/lib/python3.12/site-packages/transformers/modeling_utils.py", line 1109, in _get_resolved_checkpoint_files
    if has_file(pretrained_model_name_or_path, TF2_WEIGHTS_NAME, **has_file_kwargs):
       ^^^^^^^^^^^^^^^^^^^^^^^^^^^^^^^^^^^^^^^^^^^^^^^^^^^^^^^^^^^^^^^^^^^^^^^^^^^^
  File "/usr/local/lib/python3.12/site-packages/transformers/utils/hub.py", line 686, in has_file
    response = get_session().head(
               ^^^^^^^^^^^^^^^^^^^
  File "/usr/local/lib/python3.12/site-packages/requests/sessions.py", line 624, in head
    return self.request("HEAD", url, **kwargs)
           ^^^^^^^^^^^^^^^^^^^^^^^^^^^^^^^^^^^
  File "/usr/local/lib/python3.12/site-packages/requests/sessions.py", line 589, in request
    resp = self.send(prep, **send_kwargs)
           ^^^^^^^^^^^^^^^^^^^^^^^^^^^^^^
  File "/usr/local/lib/python3.12/site-packages/requests/sessions.py", line 703, in send
    r = adapter.send(request, **kwargs)
        ^^^^^^^^^^^^^^^^^^^^^^^^^^^^^^^
  File "/usr/local/lib/python3.12/site-packages/huggingface_hub/utils/_http.py", line 96, in send
    return super().send(request, *args, **kwargs)
           ^^^^^^^^^^^^^^^^^^^^^^^^^^^^^^^^^^^^^^
  File "/usr/local/lib/python3.12/site-packages/requests/adapters.py", line 698, in send
    raise SSLError(e, request=request)
requests.exceptions.SSLError: (MaxRetryError("HTTPSConnectionPool(host='huggingface.co', port=443): Max retries exceeded with url: /distilbert-base-uncased-finetuned-sst-2-english/resolve/main/tf_model.h5 (Caused by SSLError(SSLError(1, '[SSL: WRONG_VERSION_NUMBER] wrong version number (_ssl.c:1010)')))"), '(Request ID: 0bd429b9-c933-4263-9e68-2472ca2e9ed1)')



2025-03-24 20:06:06,109 - root - ERROR - Failed to initialize model: Could not load model distilbert-base-uncased-finetuned-sst-2-english with any of the following classes: (<class 'transformers.models.auto.modeling_auto.AutoModelForSequenceClassification'>,). See the original errors:

while loading with AutoModelForSequenceClassification, an error is thrown:
Traceback (most recent call last):
  File "c:\Users\jordi\Documents\UNI\backend-jbl42\.venv\Lib\site-packages\urllib3\connectionpool.py", line 464, in _make_request
    self._validate_conn(conn)
    ~~~~~~~~~~~~~~~~~~~^^^^^^
  File "c:\Users\jordi\Documents\UNI\backend-jbl42\.venv\Lib\site-packages\urllib3\connectionpool.py", line 1093, in _validate_conn
    conn.connect()
    ~~~~~~~~~~~~^^
  File "c:\Users\jordi\Documents\UNI\backend-jbl42\.venv\Lib\site-packages\urllib3\connection.py", line 741, in connect
    sock_and_verified = _ssl_wrap_socket_and_match_hostname(
        sock=sock,
    ...<14 lines>...
        assert_fingerprint=self.assert_fingerprint,
    )
  File "c:\Users\jordi\Documents\UNI\backend-jbl42\.venv\Lib\site-packages\urllib3\connection.py", line 920, in _ssl_wrap_socket_and_match_hostname
    ssl_sock = ssl_wrap_socket(
        sock=sock,
    ...<8 lines>...
        tls_in_tls=tls_in_tls,
    )
  File "c:\Users\jordi\Documents\UNI\backend-jbl42\.venv\Lib\site-packages\urllib3\util\ssl_.py", line 460, in ssl_wrap_socket
    ssl_sock = _ssl_wrap_socket_impl(sock, context, tls_in_tls, server_hostname)
  File "c:\Users\jordi\Documents\UNI\backend-jbl42\.venv\Lib\site-packages\urllib3\util\ssl_.py", line 504, in _ssl_wrap_socket_impl
    return ssl_context.wrap_socket(sock, server_hostname=server_hostname)
           ~~~~~~~~~~~~~~~~~~~~~~~^^^^^^^^^^^^^^^^^^^^^^^^^^^^^^^^^^^^^^^
  File "C:\Program Files\WindowsApps\PythonSoftwareFoundation.Python.3.13_3.13.752.0_x64__qbz5n2kfra8p0\Lib\ssl.py", line 455, in wrap_socket
    return self.sslsocket_class._create(
           ~~~~~~~~~~~~~~~~~~~~~~~~~~~~^
        sock=sock,
        ^^^^^^^^^^
    ...<5 lines>...
        session=session
        ^^^^^^^^^^^^^^^
    )
    ^
  File "C:\Program Files\WindowsApps\PythonSoftwareFoundation.Python.3.13_3.13.752.0_x64__qbz5n2kfra8p0\Lib\ssl.py", line 1076, in _create
    self.do_handshake()
    ~~~~~~~~~~~~~~~~~^^
  File "C:\Program Files\WindowsApps\PythonSoftwareFoundation.Python.3.13_3.13.752.0_x64__qbz5n2kfra8p0\Lib\ssl.py", line 1372, in do_handshake
    self._sslobj.do_handshake()
    ~~~~~~~~~~~~~~~~~~~~~~~~~^^
ssl.SSLError: [SSL: WRONG_VERSION_NUMBER] wrong version number (_ssl.c:1028)

During handling of the above exception, another exception occurred:

Traceback (most recent call last):
  File "c:\Users\jordi\Documents\UNI\backend-jbl42\.venv\Lib\site-packages\urllib3\connectionpool.py", line 787, in urlopen
    response = self._make_request(
        conn,
    ...<10 lines>...
        **response_kw,
    )
  File "c:\Users\jordi\Documents\UNI\backend-jbl42\.venv\Lib\site-packages\urllib3\connectionpool.py", line 488, in _make_request
    raise new_e
urllib3.exceptions.SSLError: [SSL: WRONG_VERSION_NUMBER] wrong version number (_ssl.c:1028)

The above exception was the direct cause of the following exception:

Traceback (most recent call last):
  File "c:\Users\jordi\Documents\UNI\backend-jbl42\.venv\Lib\site-packages\requests\adapters.py", line 667, in send
    resp = conn.urlopen(
        method=request.method,
    ...<9 lines>...
        chunked=chunked,
    )
  File "c:\Users\jordi\Documents\UNI\backend-jbl42\.venv\Lib\site-packages\urllib3\connectionpool.py", line 841, in urlopen
    retries = retries.increment(
        method, url, error=new_e, _pool=self, _stacktrace=sys.exc_info()[2]
    )
  File "c:\Users\jordi\Documents\UNI\backend-jbl42\.venv\Lib\site-packages\urllib3\util\retry.py", line 519, in increment
    raise MaxRetryError(_pool, url, reason) from reason  # type: ignore[arg-type]
    ^^^^^^^^^^^^^^^^^^^^^^^^^^^^^^^^^^^^^^^^^^^^^^^^^^^
urllib3.exceptions.MaxRetryError: HTTPSConnectionPool(host='huggingface.co', port=443): Max retries exceeded with url: /distilbert-base-uncased-finetuned-sst-2-english/resolve/main/tf_model.h5 (Caused by SSLError(SSLError(1, '[SSL: WRONG_VERSION_NUMBER] wrong version number (_ssl.c:1028)')))

During handling of the above exception, another exception occurred:

Traceback (most recent call last):
  File "c:\Users\jordi\Documents\UNI\backend-jbl42\.venv\Lib\site-packages\transformers\pipelines\base.py", line 291, in infer_framework_load_model
    model = model_class.from_pretrained(model, **kwargs)
  File "c:\Users\jordi\Documents\UNI\backend-jbl42\.venv\Lib\site-packages\transformers\models\auto\auto_factory.py", line 573, in from_pretrained
    return model_class.from_pretrained(
           ~~~~~~~~~~~~~~~~~~~~~~~~~~~^
        pretrained_model_name_or_path, *model_args, config=config, **hub_kwargs, **kwargs
        ^^^^^^^^^^^^^^^^^^^^^^^^^^^^^^^^^^^^^^^^^^^^^^^^^^^^^^^^^^^^^^^^^^^^^^^^^^^^^^^^^
    )
    ^
  File "c:\Users\jordi\Documents\UNI\backend-jbl42\.venv\Lib\site-packages\transformers\modeling_utils.py", line 272, in _wrapper
    return func(*args, **kwargs)
  File "c:\Users\jordi\Documents\UNI\backend-jbl42\.venv\Lib\site-packages\transformers\modeling_utils.py", line 4317, in from_pretrained
    checkpoint_files, sharded_metadata = _get_resolved_checkpoint_files(
                                         ~~~~~~~~~~~~~~~~~~~~~~~~~~~~~~^
        pretrained_model_name_or_path=pretrained_model_name_or_path,
        ^^^^^^^^^^^^^^^^^^^^^^^^^^^^^^^^^^^^^^^^^^^^^^^^^^^^^^^^^^^^
    ...<13 lines>...
        commit_hash=commit_hash,
        ^^^^^^^^^^^^^^^^^^^^^^^^
    )
    ^
  File "c:\Users\jordi\Documents\UNI\backend-jbl42\.venv\Lib\site-packages\transformers\modeling_utils.py", line 1109, in _get_resolved_checkpoint_files
    if has_file(pretrained_model_name_or_path, TF2_WEIGHTS_NAME, **has_file_kwargs):
       ~~~~~~~~^^^^^^^^^^^^^^^^^^^^^^^^^^^^^^^^^^^^^^^^^^^^^^^^^^^^^^^^^^^^^^^^^^^^
  File "c:\Users\jordi\Documents\UNI\backend-jbl42\.venv\Lib\site-packages\transformers\utils\hub.py", line 686, in has_file
    response = get_session().head(
        hf_hub_url(path_or_repo, filename=filename, revision=revision, repo_type=repo_type),
    ...<3 lines>...
        timeout=10,
    )
  File "c:\Users\jordi\Documents\UNI\backend-jbl42\.venv\Lib\site-packages\requests\sessions.py", line 624, in head
    return self.request("HEAD", url, **kwargs)
           ~~~~~~~~~~~~^^^^^^^^^^^^^^^^^^^^^^^
  File "c:\Users\jordi\Documents\UNI\backend-jbl42\.venv\Lib\site-packages\requests\sessions.py", line 589, in request
    resp = self.send(prep, **send_kwargs)
  File "c:\Users\jordi\Documents\UNI\backend-jbl42\.venv\Lib\site-packages\requests\sessions.py", line 703, in send
    r = adapter.send(request, **kwargs)
  File "c:\Users\jordi\Documents\UNI\backend-jbl42\.venv\Lib\site-packages\huggingface_hub\utils\_http.py", line 96, in send
    return super().send(request, *args, **kwargs)
           ~~~~~~~~~~~~^^^^^^^^^^^^^^^^^^^^^^^^^^
  File "c:\Users\jordi\Documents\UNI\backend-jbl42\.venv\Lib\site-packages\requests\adapters.py", line 698, in send
    raise SSLError(e, request=request)
requests.exceptions.SSLError: (MaxRetryError("HTTPSConnectionPool(host='huggingface.co', port=443): Max retries exceeded with url: /distilbert-base-uncased-finetuned-sst-2-english/resolve/main/tf_model.h5 (Caused by SSLError(SSLError(1, '[SSL: WRONG_VERSION_NUMBER] wrong version number (_ssl.c:1028)')))"), '(Request ID: 164b20d6-20b9-4aee-b8d6-f695554c7a94)')



2025-03-24 19:13:43,219 - root - ERROR - Failed to initialize model: Could not load model distilbert-base-uncased-finetuned-sst-2-english with any of the following classes: (<class 'transformers.models.auto.modeling_auto.AutoModelForSequenceClassification'>,). See the original errors:

while loading with AutoModelForSequenceClassification, an error is thrown:
Traceback (most recent call last):
  File "/usr/local/lib/python3.12/site-packages/urllib3/connectionpool.py", line 464, in _make_request
    self._validate_conn(conn)
  File "/usr/local/lib/python3.12/site-packages/urllib3/connectionpool.py", line 1093, in _validate_conn
    conn.connect()
  File "/usr/local/lib/python3.12/site-packages/urllib3/connection.py", line 741, in connect
    sock_and_verified = _ssl_wrap_socket_and_match_hostname(
                        ^^^^^^^^^^^^^^^^^^^^^^^^^^^^^^^^^^^^
  File "/usr/local/lib/python3.12/site-packages/urllib3/connection.py", line 920, in _ssl_wrap_socket_and_match_hostname
    ssl_sock = ssl_wrap_socket(
               ^^^^^^^^^^^^^^^^
  File "/usr/local/lib/python3.12/site-packages/urllib3/util/ssl_.py", line 460, in ssl_wrap_socket
    ssl_sock = _ssl_wrap_socket_impl(sock, context, tls_in_tls, server_hostname)
               ^^^^^^^^^^^^^^^^^^^^^^^^^^^^^^^^^^^^^^^^^^^^^^^^^^^^^^^^^^^^^^^^^
  File "/usr/local/lib/python3.12/site-packages/urllib3/util/ssl_.py", line 504, in _ssl_wrap_socket_impl
    return ssl_context.wrap_socket(sock, server_hostname=server_hostname)
           ^^^^^^^^^^^^^^^^^^^^^^^^^^^^^^^^^^^^^^^^^^^^^^^^^^^^^^^^^^^^^^
  File "/usr/local/lib/python3.12/ssl.py", line 455, in wrap_socket
    return self.sslsocket_class._create(
           ^^^^^^^^^^^^^^^^^^^^^^^^^^^^^
  File "/usr/local/lib/python3.12/ssl.py", line 1041, in _create
    self.do_handshake()
  File "/usr/local/lib/python3.12/ssl.py", line 1319, in do_handshake
    self._sslobj.do_handshake()
ssl.SSLError: [SSL: WRONG_VERSION_NUMBER] wrong version number (_ssl.c:1010)

During handling of the above exception, another exception occurred:

Traceback (most recent call last):
  File "/usr/local/lib/python3.12/site-packages/urllib3/connectionpool.py", line 787, in urlopen
    response = self._make_request(
               ^^^^^^^^^^^^^^^^^^^
  File "/usr/local/lib/python3.12/site-packages/urllib3/connectionpool.py", line 488, in _make_request
    raise new_e
urllib3.exceptions.SSLError: [SSL: WRONG_VERSION_NUMBER] wrong version number (_ssl.c:1010)

The above exception was the direct cause of the following exception:

Traceback (most recent call last):
  File "/usr/local/lib/python3.12/site-packages/requests/adapters.py", line 667, in send
    resp = conn.urlopen(
           ^^^^^^^^^^^^^
  File "/usr/local/lib/python3.12/site-packages/urllib3/connectionpool.py", line 841, in urlopen
    retries = retries.increment(
              ^^^^^^^^^^^^^^^^^^
  File "/usr/local/lib/python3.12/site-packages/urllib3/util/retry.py", line 519, in increment
    raise MaxRetryError(_pool, url, reason) from reason  # type: ignore[arg-type]
    ^^^^^^^^^^^^^^^^^^^^^^^^^^^^^^^^^^^^^^^^^^^^^^^^^^^
urllib3.exceptions.MaxRetryError: HTTPSConnectionPool(host='huggingface.co', port=443): Max retries exceeded with url: /distilbert-base-uncased-finetuned-sst-2-english/resolve/main/tf_model.h5 (Caused by SSLError(SSLError(1, '[SSL: WRONG_VERSION_NUMBER] wrong version number (_ssl.c:1010)')))

During handling of the above exception, another exception occurred:

Traceback (most recent call last):
  File "/usr/local/lib/python3.12/site-packages/transformers/pipelines/base.py", line 291, in infer_framework_load_model
    model = model_class.from_pretrained(model, **kwargs)
            ^^^^^^^^^^^^^^^^^^^^^^^^^^^^^^^^^^^^^^^^^^^^
  File "/usr/local/lib/python3.12/site-packages/transformers/models/auto/auto_factory.py", line 573, in from_pretrained
    return model_class.from_pretrained(
           ^^^^^^^^^^^^^^^^^^^^^^^^^^^^
  File "/usr/local/lib/python3.12/site-packages/transformers/modeling_utils.py", line 272, in _wrapper
    return func(*args, **kwargs)
           ^^^^^^^^^^^^^^^^^^^^^
  File "/usr/local/lib/python3.12/site-packages/transformers/modeling_utils.py", line 4317, in from_pretrained
    checkpoint_files, sharded_metadata = _get_resolved_checkpoint_files(
                                         ^^^^^^^^^^^^^^^^^^^^^^^^^^^^^^^
  File "/usr/local/lib/python3.12/site-packages/transformers/modeling_utils.py", line 1109, in _get_resolved_checkpoint_files
    if has_file(pretrained_model_name_or_path, TF2_WEIGHTS_NAME, **has_file_kwargs):
       ^^^^^^^^^^^^^^^^^^^^^^^^^^^^^^^^^^^^^^^^^^^^^^^^^^^^^^^^^^^^^^^^^^^^^^^^^^^^
  File "/usr/local/lib/python3.12/site-packages/transformers/utils/hub.py", line 686, in has_file
    response = get_session().head(
               ^^^^^^^^^^^^^^^^^^^
  File "/usr/local/lib/python3.12/site-packages/requests/sessions.py", line 624, in head
    return self.request("HEAD", url, **kwargs)
           ^^^^^^^^^^^^^^^^^^^^^^^^^^^^^^^^^^^
  File "/usr/local/lib/python3.12/site-packages/requests/sessions.py", line 589, in request
    resp = self.send(prep, **send_kwargs)
           ^^^^^^^^^^^^^^^^^^^^^^^^^^^^^^
  File "/usr/local/lib/python3.12/site-packages/requests/sessions.py", line 703, in send
    r = adapter.send(request, **kwargs)
        ^^^^^^^^^^^^^^^^^^^^^^^^^^^^^^^
  File "/usr/local/lib/python3.12/site-packages/huggingface_hub/utils/_http.py", line 96, in send
    return super().send(request, *args, **kwargs)
           ^^^^^^^^^^^^^^^^^^^^^^^^^^^^^^^^^^^^^^
  File "/usr/local/lib/python3.12/site-packages/requests/adapters.py", line 698, in send
    raise SSLError(e, request=request)
requests.exceptions.SSLError: (MaxRetryError("HTTPSConnectionPool(host='huggingface.co', port=443): Max retries exceeded with url: /distilbert-base-uncased-finetuned-sst-2-english/resolve/main/tf_model.h5 (Caused by SSLError(SSLError(1, '[SSL: WRONG_VERSION_NUMBER] wrong version number (_ssl.c:1010)')))"), '(Request ID: 32136861-4a3c-4005-81fa-23fad7b084a0)')



2025-03-24 19:18:53,208 - root - ERROR - Failed to initialize model: Could not load model distilbert-base-uncased-finetuned-sst-2-english with any of the following classes: (<class 'transformers.models.auto.modeling_auto.AutoModelForSequenceClassification'>,). See the original errors:

while loading with AutoModelForSequenceClassification, an error is thrown:
Traceback (most recent call last):
  File "/usr/local/lib/python3.12/site-packages/urllib3/connectionpool.py", line 464, in _make_request
    self._validate_conn(conn)
  File "/usr/local/lib/python3.12/site-packages/urllib3/connectionpool.py", line 1093, in _validate_conn
    conn.connect()
  File "/usr/local/lib/python3.12/site-packages/urllib3/connection.py", line 741, in connect
    sock_and_verified = _ssl_wrap_socket_and_match_hostname(
                        ^^^^^^^^^^^^^^^^^^^^^^^^^^^^^^^^^^^^
  File "/usr/local/lib/python3.12/site-packages/urllib3/connection.py", line 920, in _ssl_wrap_socket_and_match_hostname
    ssl_sock = ssl_wrap_socket(
               ^^^^^^^^^^^^^^^^
  File "/usr/local/lib/python3.12/site-packages/urllib3/util/ssl_.py", line 460, in ssl_wrap_socket
    ssl_sock = _ssl_wrap_socket_impl(sock, context, tls_in_tls, server_hostname)
               ^^^^^^^^^^^^^^^^^^^^^^^^^^^^^^^^^^^^^^^^^^^^^^^^^^^^^^^^^^^^^^^^^
  File "/usr/local/lib/python3.12/site-packages/urllib3/util/ssl_.py", line 504, in _ssl_wrap_socket_impl
    return ssl_context.wrap_socket(sock, server_hostname=server_hostname)
           ^^^^^^^^^^^^^^^^^^^^^^^^^^^^^^^^^^^^^^^^^^^^^^^^^^^^^^^^^^^^^^
  File "/usr/local/lib/python3.12/ssl.py", line 455, in wrap_socket
    return self.sslsocket_class._create(
           ^^^^^^^^^^^^^^^^^^^^^^^^^^^^^
  File "/usr/local/lib/python3.12/ssl.py", line 1041, in _create
    self.do_handshake()
  File "/usr/local/lib/python3.12/ssl.py", line 1319, in do_handshake
    self._sslobj.do_handshake()
ssl.SSLError: [SSL: WRONG_VERSION_NUMBER] wrong version number (_ssl.c:1010)

During handling of the above exception, another exception occurred:

Traceback (most recent call last):
  File "/usr/local/lib/python3.12/site-packages/urllib3/connectionpool.py", line 787, in urlopen
    response = self._make_request(
               ^^^^^^^^^^^^^^^^^^^
  File "/usr/local/lib/python3.12/site-packages/urllib3/connectionpool.py", line 488, in _make_request
    raise new_e
urllib3.exceptions.SSLError: [SSL: WRONG_VERSION_NUMBER] wrong version number (_ssl.c:1010)

The above exception was the direct cause of the following exception:

Traceback (most recent call last):
  File "/usr/local/lib/python3.12/site-packages/requests/adapters.py", line 667, in send
    resp = conn.urlopen(
           ^^^^^^^^^^^^^
  File "/usr/local/lib/python3.12/site-packages/urllib3/connectionpool.py", line 841, in urlopen
    retries = retries.increment(
              ^^^^^^^^^^^^^^^^^^
  File "/usr/local/lib/python3.12/site-packages/urllib3/util/retry.py", line 519, in increment
    raise MaxRetryError(_pool, url, reason) from reason  # type: ignore[arg-type]
    ^^^^^^^^^^^^^^^^^^^^^^^^^^^^^^^^^^^^^^^^^^^^^^^^^^^
urllib3.exceptions.MaxRetryError: HTTPSConnectionPool(host='huggingface.co', port=443): Max retries exceeded with url: /distilbert-base-uncased-finetuned-sst-2-english/resolve/main/tf_model.h5 (Caused by SSLError(SSLError(1, '[SSL: WRONG_VERSION_NUMBER] wrong version number (_ssl.c:1010)')))

During handling of the above exception, another exception occurred:

Traceback (most recent call last):
  File "/usr/local/lib/python3.12/site-packages/transformers/pipelines/base.py", line 291, in infer_framework_load_model
    model = model_class.from_pretrained(model, **kwargs)
            ^^^^^^^^^^^^^^^^^^^^^^^^^^^^^^^^^^^^^^^^^^^^
  File "/usr/local/lib/python3.12/site-packages/transformers/models/auto/auto_factory.py", line 573, in from_pretrained
    return model_class.from_pretrained(
           ^^^^^^^^^^^^^^^^^^^^^^^^^^^^
  File "/usr/local/lib/python3.12/site-packages/transformers/modeling_utils.py", line 272, in _wrapper
    return func(*args, **kwargs)
           ^^^^^^^^^^^^^^^^^^^^^
  File "/usr/local/lib/python3.12/site-packages/transformers/modeling_utils.py", line 4317, in from_pretrained
    checkpoint_files, sharded_metadata = _get_resolved_checkpoint_files(
                                         ^^^^^^^^^^^^^^^^^^^^^^^^^^^^^^^
  File "/usr/local/lib/python3.12/site-packages/transformers/modeling_utils.py", line 1109, in _get_resolved_checkpoint_files
    if has_file(pretrained_model_name_or_path, TF2_WEIGHTS_NAME, **has_file_kwargs):
       ^^^^^^^^^^^^^^^^^^^^^^^^^^^^^^^^^^^^^^^^^^^^^^^^^^^^^^^^^^^^^^^^^^^^^^^^^^^^
  File "/usr/local/lib/python3.12/site-packages/transformers/utils/hub.py", line 686, in has_file
    response = get_session().head(
               ^^^^^^^^^^^^^^^^^^^
  File "/usr/local/lib/python3.12/site-packages/requests/sessions.py", line 624, in head
    return self.request("HEAD", url, **kwargs)
           ^^^^^^^^^^^^^^^^^^^^^^^^^^^^^^^^^^^
  File "/usr/local/lib/python3.12/site-packages/requests/sessions.py", line 589, in request
    resp = self.send(prep, **send_kwargs)
           ^^^^^^^^^^^^^^^^^^^^^^^^^^^^^^
  File "/usr/local/lib/python3.12/site-packages/requests/sessions.py", line 703, in send
    r = adapter.send(request, **kwargs)
        ^^^^^^^^^^^^^^^^^^^^^^^^^^^^^^^
  File "/usr/local/lib/python3.12/site-packages/huggingface_hub/utils/_http.py", line 96, in send
    return super().send(request, *args, **kwargs)
           ^^^^^^^^^^^^^^^^^^^^^^^^^^^^^^^^^^^^^^
  File "/usr/local/lib/python3.12/site-packages/requests/adapters.py", line 698, in send
    raise SSLError(e, request=request)
requests.exceptions.SSLError: (MaxRetryError("HTTPSConnectionPool(host='huggingface.co', port=443): Max retries exceeded with url: /distilbert-base-uncased-finetuned-sst-2-english/resolve/main/tf_model.h5 (Caused by SSLError(SSLError(1, '[SSL: WRONG_VERSION_NUMBER] wrong version number (_ssl.c:1010)')))"), '(Request ID: 9613d3e2-9f81-4564-b9b9-c8d14dda31b3)')



2025-03-24 19:25:30,850 - root - ERROR - Failed to initialize model: Could not load model distilbert-base-uncased-finetuned-sst-2-english with any of the following classes: (<class 'transformers.models.auto.modeling_auto.AutoModelForSequenceClassification'>,). See the original errors:

while loading with AutoModelForSequenceClassification, an error is thrown:
Traceback (most recent call last):
  File "/usr/local/lib/python3.12/site-packages/urllib3/connectionpool.py", line 464, in _make_request
    self._validate_conn(conn)
  File "/usr/local/lib/python3.12/site-packages/urllib3/connectionpool.py", line 1093, in _validate_conn
    conn.connect()
  File "/usr/local/lib/python3.12/site-packages/urllib3/connection.py", line 741, in connect
    sock_and_verified = _ssl_wrap_socket_and_match_hostname(
                        ^^^^^^^^^^^^^^^^^^^^^^^^^^^^^^^^^^^^
  File "/usr/local/lib/python3.12/site-packages/urllib3/connection.py", line 920, in _ssl_wrap_socket_and_match_hostname
    ssl_sock = ssl_wrap_socket(
               ^^^^^^^^^^^^^^^^
  File "/usr/local/lib/python3.12/site-packages/urllib3/util/ssl_.py", line 460, in ssl_wrap_socket
    ssl_sock = _ssl_wrap_socket_impl(sock, context, tls_in_tls, server_hostname)
               ^^^^^^^^^^^^^^^^^^^^^^^^^^^^^^^^^^^^^^^^^^^^^^^^^^^^^^^^^^^^^^^^^
  File "/usr/local/lib/python3.12/site-packages/urllib3/util/ssl_.py", line 504, in _ssl_wrap_socket_impl
    return ssl_context.wrap_socket(sock, server_hostname=server_hostname)
           ^^^^^^^^^^^^^^^^^^^^^^^^^^^^^^^^^^^^^^^^^^^^^^^^^^^^^^^^^^^^^^
  File "/usr/local/lib/python3.12/ssl.py", line 455, in wrap_socket
    return self.sslsocket_class._create(
           ^^^^^^^^^^^^^^^^^^^^^^^^^^^^^
  File "/usr/local/lib/python3.12/ssl.py", line 1041, in _create
    self.do_handshake()
  File "/usr/local/lib/python3.12/ssl.py", line 1319, in do_handshake
    self._sslobj.do_handshake()
ssl.SSLError: [SSL: WRONG_VERSION_NUMBER] wrong version number (_ssl.c:1010)

During handling of the above exception, another exception occurred:

Traceback (most recent call last):
  File "/usr/local/lib/python3.12/site-packages/urllib3/connectionpool.py", line 787, in urlopen
    response = self._make_request(
               ^^^^^^^^^^^^^^^^^^^
  File "/usr/local/lib/python3.12/site-packages/urllib3/connectionpool.py", line 488, in _make_request
    raise new_e
urllib3.exceptions.SSLError: [SSL: WRONG_VERSION_NUMBER] wrong version number (_ssl.c:1010)

The above exception was the direct cause of the following exception:

Traceback (most recent call last):
  File "/usr/local/lib/python3.12/site-packages/requests/adapters.py", line 667, in send
    resp = conn.urlopen(
           ^^^^^^^^^^^^^
  File "/usr/local/lib/python3.12/site-packages/urllib3/connectionpool.py", line 841, in urlopen
    retries = retries.increment(
              ^^^^^^^^^^^^^^^^^^
  File "/usr/local/lib/python3.12/site-packages/urllib3/util/retry.py", line 519, in increment
    raise MaxRetryError(_pool, url, reason) from reason  # type: ignore[arg-type]
    ^^^^^^^^^^^^^^^^^^^^^^^^^^^^^^^^^^^^^^^^^^^^^^^^^^^
urllib3.exceptions.MaxRetryError: HTTPSConnectionPool(host='huggingface.co', port=443): Max retries exceeded with url: /distilbert-base-uncased-finetuned-sst-2-english/resolve/main/tf_model.h5 (Caused by SSLError(SSLError(1, '[SSL: WRONG_VERSION_NUMBER] wrong version number (_ssl.c:1010)')))

During handling of the above exception, another exception occurred:

Traceback (most recent call last):
  File "/usr/local/lib/python3.12/site-packages/transformers/pipelines/base.py", line 291, in infer_framework_load_model
    model = model_class.from_pretrained(model, **kwargs)
            ^^^^^^^^^^^^^^^^^^^^^^^^^^^^^^^^^^^^^^^^^^^^
  File "/usr/local/lib/python3.12/site-packages/transformers/models/auto/auto_factory.py", line 573, in from_pretrained
    return model_class.from_pretrained(
           ^^^^^^^^^^^^^^^^^^^^^^^^^^^^
  File "/usr/local/lib/python3.12/site-packages/transformers/modeling_utils.py", line 272, in _wrapper
    return func(*args, **kwargs)
           ^^^^^^^^^^^^^^^^^^^^^
  File "/usr/local/lib/python3.12/site-packages/transformers/modeling_utils.py", line 4317, in from_pretrained
    checkpoint_files, sharded_metadata = _get_resolved_checkpoint_files(
                                         ^^^^^^^^^^^^^^^^^^^^^^^^^^^^^^^
  File "/usr/local/lib/python3.12/site-packages/transformers/modeling_utils.py", line 1109, in _get_resolved_checkpoint_files
    if has_file(pretrained_model_name_or_path, TF2_WEIGHTS_NAME, **has_file_kwargs):
       ^^^^^^^^^^^^^^^^^^^^^^^^^^^^^^^^^^^^^^^^^^^^^^^^^^^^^^^^^^^^^^^^^^^^^^^^^^^^
  File "/usr/local/lib/python3.12/site-packages/transformers/utils/hub.py", line 686, in has_file
    response = get_session().head(
               ^^^^^^^^^^^^^^^^^^^
  File "/usr/local/lib/python3.12/site-packages/requests/sessions.py", line 624, in head
    return self.request("HEAD", url, **kwargs)
           ^^^^^^^^^^^^^^^^^^^^^^^^^^^^^^^^^^^
  File "/usr/local/lib/python3.12/site-packages/requests/sessions.py", line 589, in request
    resp = self.send(prep, **send_kwargs)
           ^^^^^^^^^^^^^^^^^^^^^^^^^^^^^^
  File "/usr/local/lib/python3.12/site-packages/requests/sessions.py", line 703, in send
    r = adapter.send(request, **kwargs)
        ^^^^^^^^^^^^^^^^^^^^^^^^^^^^^^^
  File "/usr/local/lib/python3.12/site-packages/huggingface_hub/utils/_http.py", line 96, in send
    return super().send(request, *args, **kwargs)
           ^^^^^^^^^^^^^^^^^^^^^^^^^^^^^^^^^^^^^^
  File "/usr/local/lib/python3.12/site-packages/requests/adapters.py", line 698, in send
    raise SSLError(e, request=request)
requests.exceptions.SSLError: (MaxRetryError("HTTPSConnectionPool(host='huggingface.co', port=443): Max retries exceeded with url: /distilbert-base-uncased-finetuned-sst-2-english/resolve/main/tf_model.h5 (Caused by SSLError(SSLError(1, '[SSL: WRONG_VERSION_NUMBER] wrong version number (_ssl.c:1010)')))"), '(Request ID: 9be4e593-7f2c-4081-b211-1775a43bdd31)')



2025-03-24 19:29:03,294 - root - ERROR - Failed to initialize model: Could not load model distilbert-base-uncased-finetuned-sst-2-english with any of the following classes: (<class 'transformers.models.auto.modeling_auto.AutoModelForSequenceClassification'>,). See the original errors:

while loading with AutoModelForSequenceClassification, an error is thrown:
Traceback (most recent call last):
  File "/usr/local/lib/python3.12/site-packages/urllib3/connectionpool.py", line 464, in _make_request
    self._validate_conn(conn)
  File "/usr/local/lib/python3.12/site-packages/urllib3/connectionpool.py", line 1093, in _validate_conn
    conn.connect()
  File "/usr/local/lib/python3.12/site-packages/urllib3/connection.py", line 741, in connect
    sock_and_verified = _ssl_wrap_socket_and_match_hostname(
                        ^^^^^^^^^^^^^^^^^^^^^^^^^^^^^^^^^^^^
  File "/usr/local/lib/python3.12/site-packages/urllib3/connection.py", line 920, in _ssl_wrap_socket_and_match_hostname
    ssl_sock = ssl_wrap_socket(
               ^^^^^^^^^^^^^^^^
  File "/usr/local/lib/python3.12/site-packages/urllib3/util/ssl_.py", line 460, in ssl_wrap_socket
    ssl_sock = _ssl_wrap_socket_impl(sock, context, tls_in_tls, server_hostname)
               ^^^^^^^^^^^^^^^^^^^^^^^^^^^^^^^^^^^^^^^^^^^^^^^^^^^^^^^^^^^^^^^^^
  File "/usr/local/lib/python3.12/site-packages/urllib3/util/ssl_.py", line 504, in _ssl_wrap_socket_impl
    return ssl_context.wrap_socket(sock, server_hostname=server_hostname)
           ^^^^^^^^^^^^^^^^^^^^^^^^^^^^^^^^^^^^^^^^^^^^^^^^^^^^^^^^^^^^^^
  File "/usr/local/lib/python3.12/ssl.py", line 455, in wrap_socket
    return self.sslsocket_class._create(
           ^^^^^^^^^^^^^^^^^^^^^^^^^^^^^
  File "/usr/local/lib/python3.12/ssl.py", line 1041, in _create
    self.do_handshake()
  File "/usr/local/lib/python3.12/ssl.py", line 1319, in do_handshake
    self._sslobj.do_handshake()
ssl.SSLError: [SSL: WRONG_VERSION_NUMBER] wrong version number (_ssl.c:1010)

During handling of the above exception, another exception occurred:

Traceback (most recent call last):
  File "/usr/local/lib/python3.12/site-packages/urllib3/connectionpool.py", line 787, in urlopen
    response = self._make_request(
               ^^^^^^^^^^^^^^^^^^^
  File "/usr/local/lib/python3.12/site-packages/urllib3/connectionpool.py", line 488, in _make_request
    raise new_e
urllib3.exceptions.SSLError: [SSL: WRONG_VERSION_NUMBER] wrong version number (_ssl.c:1010)

The above exception was the direct cause of the following exception:

Traceback (most recent call last):
  File "/usr/local/lib/python3.12/site-packages/requests/adapters.py", line 667, in send
    resp = conn.urlopen(
           ^^^^^^^^^^^^^
  File "/usr/local/lib/python3.12/site-packages/urllib3/connectionpool.py", line 841, in urlopen
    retries = retries.increment(
              ^^^^^^^^^^^^^^^^^^
  File "/usr/local/lib/python3.12/site-packages/urllib3/util/retry.py", line 519, in increment
    raise MaxRetryError(_pool, url, reason) from reason  # type: ignore[arg-type]
    ^^^^^^^^^^^^^^^^^^^^^^^^^^^^^^^^^^^^^^^^^^^^^^^^^^^
urllib3.exceptions.MaxRetryError: HTTPSConnectionPool(host='huggingface.co', port=443): Max retries exceeded with url: /distilbert-base-uncased-finetuned-sst-2-english/resolve/main/tf_model.h5 (Caused by SSLError(SSLError(1, '[SSL: WRONG_VERSION_NUMBER] wrong version number (_ssl.c:1010)')))

During handling of the above exception, another exception occurred:

Traceback (most recent call last):
  File "/usr/local/lib/python3.12/site-packages/transformers/pipelines/base.py", line 291, in infer_framework_load_model
    model = model_class.from_pretrained(model, **kwargs)
            ^^^^^^^^^^^^^^^^^^^^^^^^^^^^^^^^^^^^^^^^^^^^
  File "/usr/local/lib/python3.12/site-packages/transformers/models/auto/auto_factory.py", line 573, in from_pretrained
    return model_class.from_pretrained(
           ^^^^^^^^^^^^^^^^^^^^^^^^^^^^
  File "/usr/local/lib/python3.12/site-packages/transformers/modeling_utils.py", line 272, in _wrapper
    return func(*args, **kwargs)
           ^^^^^^^^^^^^^^^^^^^^^
  File "/usr/local/lib/python3.12/site-packages/transformers/modeling_utils.py", line 4317, in from_pretrained
    checkpoint_files, sharded_metadata = _get_resolved_checkpoint_files(
                                         ^^^^^^^^^^^^^^^^^^^^^^^^^^^^^^^
  File "/usr/local/lib/python3.12/site-packages/transformers/modeling_utils.py", line 1109, in _get_resolved_checkpoint_files
    if has_file(pretrained_model_name_or_path, TF2_WEIGHTS_NAME, **has_file_kwargs):
       ^^^^^^^^^^^^^^^^^^^^^^^^^^^^^^^^^^^^^^^^^^^^^^^^^^^^^^^^^^^^^^^^^^^^^^^^^^^^
  File "/usr/local/lib/python3.12/site-packages/transformers/utils/hub.py", line 686, in has_file
    response = get_session().head(
               ^^^^^^^^^^^^^^^^^^^
  File "/usr/local/lib/python3.12/site-packages/requests/sessions.py", line 624, in head
    return self.request("HEAD", url, **kwargs)
           ^^^^^^^^^^^^^^^^^^^^^^^^^^^^^^^^^^^
  File "/usr/local/lib/python3.12/site-packages/requests/sessions.py", line 589, in request
    resp = self.send(prep, **send_kwargs)
           ^^^^^^^^^^^^^^^^^^^^^^^^^^^^^^
  File "/usr/local/lib/python3.12/site-packages/requests/sessions.py", line 703, in send
    r = adapter.send(request, **kwargs)
        ^^^^^^^^^^^^^^^^^^^^^^^^^^^^^^^
  File "/usr/local/lib/python3.12/site-packages/huggingface_hub/utils/_http.py", line 96, in send
    return super().send(request, *args, **kwargs)
           ^^^^^^^^^^^^^^^^^^^^^^^^^^^^^^^^^^^^^^
  File "/usr/local/lib/python3.12/site-packages/requests/adapters.py", line 698, in send
    raise SSLError(e, request=request)
requests.exceptions.SSLError: (MaxRetryError("HTTPSConnectionPool(host='huggingface.co', port=443): Max retries exceeded with url: /distilbert-base-uncased-finetuned-sst-2-english/resolve/main/tf_model.h5 (Caused by SSLError(SSLError(1, '[SSL: WRONG_VERSION_NUMBER] wrong version number (_ssl.c:1010)')))"), '(Request ID: dcbcd730-ddc7-4d63-86f3-09953f551ebe)')



2025-03-24 19:31:26,206 - root - ERROR - Failed to initialize model: Could not load model distilbert-base-uncased-finetuned-sst-2-english with any of the following classes: (<class 'transformers.models.auto.modeling_auto.AutoModelForSequenceClassification'>,). See the original errors:

while loading with AutoModelForSequenceClassification, an error is thrown:
Traceback (most recent call last):
  File "/usr/local/lib/python3.12/site-packages/urllib3/connectionpool.py", line 464, in _make_request
    self._validate_conn(conn)
  File "/usr/local/lib/python3.12/site-packages/urllib3/connectionpool.py", line 1093, in _validate_conn
    conn.connect()
  File "/usr/local/lib/python3.12/site-packages/urllib3/connection.py", line 741, in connect
    sock_and_verified = _ssl_wrap_socket_and_match_hostname(
                        ^^^^^^^^^^^^^^^^^^^^^^^^^^^^^^^^^^^^
  File "/usr/local/lib/python3.12/site-packages/urllib3/connection.py", line 920, in _ssl_wrap_socket_and_match_hostname
    ssl_sock = ssl_wrap_socket(
               ^^^^^^^^^^^^^^^^
  File "/usr/local/lib/python3.12/site-packages/urllib3/util/ssl_.py", line 460, in ssl_wrap_socket
    ssl_sock = _ssl_wrap_socket_impl(sock, context, tls_in_tls, server_hostname)
               ^^^^^^^^^^^^^^^^^^^^^^^^^^^^^^^^^^^^^^^^^^^^^^^^^^^^^^^^^^^^^^^^^
  File "/usr/local/lib/python3.12/site-packages/urllib3/util/ssl_.py", line 504, in _ssl_wrap_socket_impl
    return ssl_context.wrap_socket(sock, server_hostname=server_hostname)
           ^^^^^^^^^^^^^^^^^^^^^^^^^^^^^^^^^^^^^^^^^^^^^^^^^^^^^^^^^^^^^^
  File "/usr/local/lib/python3.12/ssl.py", line 455, in wrap_socket
    return self.sslsocket_class._create(
           ^^^^^^^^^^^^^^^^^^^^^^^^^^^^^
  File "/usr/local/lib/python3.12/ssl.py", line 1041, in _create
    self.do_handshake()
  File "/usr/local/lib/python3.12/ssl.py", line 1319, in do_handshake
    self._sslobj.do_handshake()
ssl.SSLError: [SSL: WRONG_VERSION_NUMBER] wrong version number (_ssl.c:1010)

During handling of the above exception, another exception occurred:

Traceback (most recent call last):
  File "/usr/local/lib/python3.12/site-packages/urllib3/connectionpool.py", line 787, in urlopen
    response = self._make_request(
               ^^^^^^^^^^^^^^^^^^^
  File "/usr/local/lib/python3.12/site-packages/urllib3/connectionpool.py", line 488, in _make_request
    raise new_e
urllib3.exceptions.SSLError: [SSL: WRONG_VERSION_NUMBER] wrong version number (_ssl.c:1010)

The above exception was the direct cause of the following exception:

Traceback (most recent call last):
  File "/usr/local/lib/python3.12/site-packages/requests/adapters.py", line 667, in send
    resp = conn.urlopen(
           ^^^^^^^^^^^^^
  File "/usr/local/lib/python3.12/site-packages/urllib3/connectionpool.py", line 841, in urlopen
    retries = retries.increment(
              ^^^^^^^^^^^^^^^^^^
  File "/usr/local/lib/python3.12/site-packages/urllib3/util/retry.py", line 519, in increment
    raise MaxRetryError(_pool, url, reason) from reason  # type: ignore[arg-type]
    ^^^^^^^^^^^^^^^^^^^^^^^^^^^^^^^^^^^^^^^^^^^^^^^^^^^
urllib3.exceptions.MaxRetryError: HTTPSConnectionPool(host='huggingface.co', port=443): Max retries exceeded with url: /distilbert-base-uncased-finetuned-sst-2-english/resolve/main/tf_model.h5 (Caused by SSLError(SSLError(1, '[SSL: WRONG_VERSION_NUMBER] wrong version number (_ssl.c:1010)')))

During handling of the above exception, another exception occurred:

Traceback (most recent call last):
  File "/usr/local/lib/python3.12/site-packages/transformers/pipelines/base.py", line 291, in infer_framework_load_model
    model = model_class.from_pretrained(model, **kwargs)
            ^^^^^^^^^^^^^^^^^^^^^^^^^^^^^^^^^^^^^^^^^^^^
  File "/usr/local/lib/python3.12/site-packages/transformers/models/auto/auto_factory.py", line 573, in from_pretrained
    return model_class.from_pretrained(
           ^^^^^^^^^^^^^^^^^^^^^^^^^^^^
  File "/usr/local/lib/python3.12/site-packages/transformers/modeling_utils.py", line 272, in _wrapper
    return func(*args, **kwargs)
           ^^^^^^^^^^^^^^^^^^^^^
  File "/usr/local/lib/python3.12/site-packages/transformers/modeling_utils.py", line 4317, in from_pretrained
    checkpoint_files, sharded_metadata = _get_resolved_checkpoint_files(
                                         ^^^^^^^^^^^^^^^^^^^^^^^^^^^^^^^
  File "/usr/local/lib/python3.12/site-packages/transformers/modeling_utils.py", line 1109, in _get_resolved_checkpoint_files
    if has_file(pretrained_model_name_or_path, TF2_WEIGHTS_NAME, **has_file_kwargs):
       ^^^^^^^^^^^^^^^^^^^^^^^^^^^^^^^^^^^^^^^^^^^^^^^^^^^^^^^^^^^^^^^^^^^^^^^^^^^^
  File "/usr/local/lib/python3.12/site-packages/transformers/utils/hub.py", line 686, in has_file
    response = get_session().head(
               ^^^^^^^^^^^^^^^^^^^
  File "/usr/local/lib/python3.12/site-packages/requests/sessions.py", line 624, in head
    return self.request("HEAD", url, **kwargs)
           ^^^^^^^^^^^^^^^^^^^^^^^^^^^^^^^^^^^
  File "/usr/local/lib/python3.12/site-packages/requests/sessions.py", line 589, in request
    resp = self.send(prep, **send_kwargs)
           ^^^^^^^^^^^^^^^^^^^^^^^^^^^^^^
  File "/usr/local/lib/python3.12/site-packages/requests/sessions.py", line 703, in send
    r = adapter.send(request, **kwargs)
        ^^^^^^^^^^^^^^^^^^^^^^^^^^^^^^^
  File "/usr/local/lib/python3.12/site-packages/huggingface_hub/utils/_http.py", line 96, in send
    return super().send(request, *args, **kwargs)
           ^^^^^^^^^^^^^^^^^^^^^^^^^^^^^^^^^^^^^^
  File "/usr/local/lib/python3.12/site-packages/requests/adapters.py", line 698, in send
    raise SSLError(e, request=request)
requests.exceptions.SSLError: (MaxRetryError("HTTPSConnectionPool(host='huggingface.co', port=443): Max retries exceeded with url: /distilbert-base-uncased-finetuned-sst-2-english/resolve/main/tf_model.h5 (Caused by SSLError(SSLError(1, '[SSL: WRONG_VERSION_NUMBER] wrong version number (_ssl.c:1010)')))"), '(Request ID: d3fbf776-6dc0-4531-94c7-1d26f610a287)')



2025-03-24 19:36:59,522 - root - INFO - Creando tablas y datos iniciales...
2025-03-24 19:36:59,526 - sqlalchemy.engine.Engine - INFO - SELECT DATABASE()
2025-03-24 19:36:59,527 - sqlalchemy.engine.Engine - INFO - [raw sql] {}
2025-03-24 19:36:59,528 - sqlalchemy.engine.Engine - INFO - SELECT @@sql_mode
2025-03-24 19:36:59,529 - sqlalchemy.engine.Engine - INFO - [raw sql] {}
2025-03-24 19:36:59,529 - sqlalchemy.engine.Engine - INFO - SELECT @@lower_case_table_names
2025-03-24 19:36:59,529 - sqlalchemy.engine.Engine - INFO - [raw sql] {}
2025-03-24 19:36:59,530 - sqlalchemy.engine.Engine - INFO - BEGIN (implicit)
2025-03-24 19:36:59,530 - sqlalchemy.engine.Engine - INFO - DESCRIBE `movies`.`user`
2025-03-24 19:36:59,531 - sqlalchemy.engine.Engine - INFO - [raw sql] {}
2025-03-24 19:36:59,533 - sqlalchemy.engine.Engine - INFO - DESCRIBE `movies`.`movie`
2025-03-24 19:36:59,533 - sqlalchemy.engine.Engine - INFO - [raw sql] {}
2025-03-24 19:36:59,534 - sqlalchemy.engine.Engine - INFO - DESCRIBE `movies`.`comment`
2025-03-24 19:36:59,534 - sqlalchemy.engine.Engine - INFO - [raw sql] {}
2025-03-24 19:36:59,535 - sqlalchemy.engine.Engine - INFO - 
CREATE TABLE user (
	id INTEGER NOT NULL AUTO_INCREMENT, 
	username VARCHAR(100) NOT NULL, 
	email VARCHAR(255) NOT NULL, 
	password VARCHAR(255) NOT NULL, 
	PRIMARY KEY (id)
)


2025-03-24 19:36:59,535 - sqlalchemy.engine.Engine - INFO - [no key 0.00021s] {}
2025-03-24 19:36:59,545 - sqlalchemy.engine.Engine - INFO - 
CREATE TABLE movie (
	id INTEGER NOT NULL AUTO_INCREMENT, 
	title VARCHAR(255) NOT NULL, 
	director VARCHAR(255) NOT NULL, 
	year INTEGER NOT NULL, 
	genre VARCHAR(100) NOT NULL, 
	PRIMARY KEY (id)
)


2025-03-24 19:36:59,545 - sqlalchemy.engine.Engine - INFO - [no key 0.00046s] {}
2025-03-24 19:36:59,550 - sqlalchemy.engine.Engine - INFO - 
CREATE TABLE comment (
	id INTEGER NOT NULL AUTO_INCREMENT, 
	movie_id INTEGER NOT NULL, 
	user_id INTEGER NOT NULL, 
	text VARCHAR(255) NOT NULL, 
	sentiment VARCHAR(255) NOT NULL, 
	PRIMARY KEY (id), 
	FOREIGN KEY(movie_id) REFERENCES movie (id), 
	FOREIGN KEY(user_id) REFERENCES user (id)
)


2025-03-24 19:36:59,551 - sqlalchemy.engine.Engine - INFO - [no key 0.00025s] {}
2025-03-24 19:36:59,559 - sqlalchemy.engine.Engine - INFO - COMMIT
2025-03-24 19:37:00,080 - sqlalchemy.engine.Engine - INFO - BEGIN (implicit)
2025-03-24 19:37:00,082 - sqlalchemy.engine.Engine - INFO - INSERT INTO user (username, email, password) VALUES (%(username__0)s, %(email__0)s, %(password__0)s), (%(username__1)s, %(email__1)s, %(password__1)s), (%(username__2)s, %(email__2)s, %(password__2)s) RETURNING user.id, user.id AS id__1
2025-03-24 19:37:00,082 - sqlalchemy.engine.Engine - INFO - [generated in 0.00010s (insertmanyvalues) 1/1 (ordered)] {'username__0': 'Alice', 'password__0': '$2b$12$izVHsZeMKnGtvqK6QM5jKuPXIq21It6e3M7aWVZLEvL63olvMQUPa', 'email__0': 'alice@example.com', 'username__1': 'Bob', 'password__1': '$2b$12$nB9k9nhKIOhrGRajpicSp.Glr78ZUoZ4H/FTwaQeB8OfBgZRfuIU.', 'email__1': 'bob@example.com', 'username__2': 'Charlie', 'password__2': '$2b$12$PrczEZdvtX.SdSzyuCsJneETt/qGLJ1j5IvCSNoPG1vcUWoHPxUFS', 'email__2': 'charlie@example.com'}
2025-03-24 19:37:00,085 - sqlalchemy.engine.Engine - INFO - COMMIT
2025-03-24 19:37:00,087 - sqlalchemy.engine.Engine - INFO - BEGIN (implicit)
2025-03-24 19:37:00,088 - sqlalchemy.engine.Engine - INFO - INSERT INTO movie (title, director, year, genre) VALUES (%(title__0)s, %(director__0)s, %(year__0)s, %(genre__0)s), (%(title__1)s, %(director__1)s, %(year__1)s, %(genre__1)s), (%(title__2)s, %(director__2)s, %(year__2)s, %(genre__2)s), (%(title__3)s, %(director__3)s, %(year__3)s, %(genre__3)s), (%(title__4)s, %(director__4)s, %(year__4)s, %(genre__4)s) RETURNING movie.id, movie.id AS id__1
2025-03-24 19:37:00,089 - sqlalchemy.engine.Engine - INFO - [generated in 0.00007s (insertmanyvalues) 1/1 (ordered)] {'director__0': 'Christopher Nolan', 'year__0': 2010, 'title__0': 'Inception', 'genre__0': 'Sci-Fi', 'director__1': 'Lana Wachowski, Lilly Wachowski', 'year__1': 1999, 'title__1': 'The Matrix', 'genre__1': 'Sci-Fi', 'director__2': 'Christopher Nolan', 'year__2': 2014, 'title__2': 'Interstellar', 'genre__2': 'Sci-Fi', 'director__3': 'Francis Ford Coppola', 'year__3': 1972, 'title__3': 'The Godfather', 'genre__3': 'Drama', 'director__4': 'Quentin Tarantino', 'year__4': 1994, 'title__4': 'Pulp Fiction', 'genre__4': 'Crime'}
2025-03-24 19:37:00,090 - sqlalchemy.engine.Engine - INFO - COMMIT
2025-03-24 19:37:00,091 - root - INFO - Base de datos inicializada correctamente
2025-03-24 19:37:00,257 - root - ERROR - Failed to initialize model: Could not load model distilbert-base-uncased-finetuned-sst-2-english with any of the following classes: (<class 'transformers.models.auto.modeling_auto.AutoModelForSequenceClassification'>,). See the original errors:

while loading with AutoModelForSequenceClassification, an error is thrown:
Traceback (most recent call last):
  File "/usr/local/lib/python3.12/site-packages/urllib3/connectionpool.py", line 464, in _make_request
    self._validate_conn(conn)
  File "/usr/local/lib/python3.12/site-packages/urllib3/connectionpool.py", line 1093, in _validate_conn
    conn.connect()
  File "/usr/local/lib/python3.12/site-packages/urllib3/connection.py", line 741, in connect
    sock_and_verified = _ssl_wrap_socket_and_match_hostname(
                        ^^^^^^^^^^^^^^^^^^^^^^^^^^^^^^^^^^^^
  File "/usr/local/lib/python3.12/site-packages/urllib3/connection.py", line 920, in _ssl_wrap_socket_and_match_hostname
    ssl_sock = ssl_wrap_socket(
               ^^^^^^^^^^^^^^^^
  File "/usr/local/lib/python3.12/site-packages/urllib3/util/ssl_.py", line 460, in ssl_wrap_socket
    ssl_sock = _ssl_wrap_socket_impl(sock, context, tls_in_tls, server_hostname)
               ^^^^^^^^^^^^^^^^^^^^^^^^^^^^^^^^^^^^^^^^^^^^^^^^^^^^^^^^^^^^^^^^^
  File "/usr/local/lib/python3.12/site-packages/urllib3/util/ssl_.py", line 504, in _ssl_wrap_socket_impl
    return ssl_context.wrap_socket(sock, server_hostname=server_hostname)
           ^^^^^^^^^^^^^^^^^^^^^^^^^^^^^^^^^^^^^^^^^^^^^^^^^^^^^^^^^^^^^^
  File "/usr/local/lib/python3.12/ssl.py", line 455, in wrap_socket
    return self.sslsocket_class._create(
           ^^^^^^^^^^^^^^^^^^^^^^^^^^^^^
  File "/usr/local/lib/python3.12/ssl.py", line 1041, in _create
    self.do_handshake()
  File "/usr/local/lib/python3.12/ssl.py", line 1319, in do_handshake
    self._sslobj.do_handshake()
ssl.SSLError: [SSL: WRONG_VERSION_NUMBER] wrong version number (_ssl.c:1010)

During handling of the above exception, another exception occurred:

Traceback (most recent call last):
  File "/usr/local/lib/python3.12/site-packages/urllib3/connectionpool.py", line 787, in urlopen
    response = self._make_request(
               ^^^^^^^^^^^^^^^^^^^
  File "/usr/local/lib/python3.12/site-packages/urllib3/connectionpool.py", line 488, in _make_request
    raise new_e
urllib3.exceptions.SSLError: [SSL: WRONG_VERSION_NUMBER] wrong version number (_ssl.c:1010)

The above exception was the direct cause of the following exception:

Traceback (most recent call last):
  File "/usr/local/lib/python3.12/site-packages/requests/adapters.py", line 667, in send
    resp = conn.urlopen(
           ^^^^^^^^^^^^^
  File "/usr/local/lib/python3.12/site-packages/urllib3/connectionpool.py", line 841, in urlopen
    retries = retries.increment(
              ^^^^^^^^^^^^^^^^^^
  File "/usr/local/lib/python3.12/site-packages/urllib3/util/retry.py", line 519, in increment
    raise MaxRetryError(_pool, url, reason) from reason  # type: ignore[arg-type]
    ^^^^^^^^^^^^^^^^^^^^^^^^^^^^^^^^^^^^^^^^^^^^^^^^^^^
urllib3.exceptions.MaxRetryError: HTTPSConnectionPool(host='huggingface.co', port=443): Max retries exceeded with url: /distilbert-base-uncased-finetuned-sst-2-english/resolve/main/tf_model.h5 (Caused by SSLError(SSLError(1, '[SSL: WRONG_VERSION_NUMBER] wrong version number (_ssl.c:1010)')))

During handling of the above exception, another exception occurred:

Traceback (most recent call last):
  File "/usr/local/lib/python3.12/site-packages/transformers/pipelines/base.py", line 291, in infer_framework_load_model
    model = model_class.from_pretrained(model, **kwargs)
            ^^^^^^^^^^^^^^^^^^^^^^^^^^^^^^^^^^^^^^^^^^^^
  File "/usr/local/lib/python3.12/site-packages/transformers/models/auto/auto_factory.py", line 573, in from_pretrained
    return model_class.from_pretrained(
           ^^^^^^^^^^^^^^^^^^^^^^^^^^^^
  File "/usr/local/lib/python3.12/site-packages/transformers/modeling_utils.py", line 272, in _wrapper
    return func(*args, **kwargs)
           ^^^^^^^^^^^^^^^^^^^^^
  File "/usr/local/lib/python3.12/site-packages/transformers/modeling_utils.py", line 4317, in from_pretrained
    checkpoint_files, sharded_metadata = _get_resolved_checkpoint_files(
                                         ^^^^^^^^^^^^^^^^^^^^^^^^^^^^^^^
  File "/usr/local/lib/python3.12/site-packages/transformers/modeling_utils.py", line 1109, in _get_resolved_checkpoint_files
    if has_file(pretrained_model_name_or_path, TF2_WEIGHTS_NAME, **has_file_kwargs):
       ^^^^^^^^^^^^^^^^^^^^^^^^^^^^^^^^^^^^^^^^^^^^^^^^^^^^^^^^^^^^^^^^^^^^^^^^^^^^
  File "/usr/local/lib/python3.12/site-packages/transformers/utils/hub.py", line 686, in has_file
    response = get_session().head(
               ^^^^^^^^^^^^^^^^^^^
  File "/usr/local/lib/python3.12/site-packages/requests/sessions.py", line 624, in head
    return self.request("HEAD", url, **kwargs)
           ^^^^^^^^^^^^^^^^^^^^^^^^^^^^^^^^^^^
  File "/usr/local/lib/python3.12/site-packages/requests/sessions.py", line 589, in request
    resp = self.send(prep, **send_kwargs)
           ^^^^^^^^^^^^^^^^^^^^^^^^^^^^^^
  File "/usr/local/lib/python3.12/site-packages/requests/sessions.py", line 703, in send
    r = adapter.send(request, **kwargs)
        ^^^^^^^^^^^^^^^^^^^^^^^^^^^^^^^
  File "/usr/local/lib/python3.12/site-packages/huggingface_hub/utils/_http.py", line 96, in send
    return super().send(request, *args, **kwargs)
           ^^^^^^^^^^^^^^^^^^^^^^^^^^^^^^^^^^^^^^
  File "/usr/local/lib/python3.12/site-packages/requests/adapters.py", line 698, in send
    raise SSLError(e, request=request)
requests.exceptions.SSLError: (MaxRetryError("HTTPSConnectionPool(host='huggingface.co', port=443): Max retries exceeded with url: /distilbert-base-uncased-finetuned-sst-2-english/resolve/main/tf_model.h5 (Caused by SSLError(SSLError(1, '[SSL: WRONG_VERSION_NUMBER] wrong version number (_ssl.c:1010)')))"), '(Request ID: 6149ca0e-3843-4fc2-99b1-8e27abdbe153)')



2025-03-24 19:40:19,478 - root - INFO - Aplicación terminando...
2025-03-24 19:41:58,506 - root - INFO - Creando tablas y datos iniciales...
2025-03-24 19:41:58,509 - sqlalchemy.engine.Engine - INFO - SELECT DATABASE()
2025-03-24 19:41:58,509 - sqlalchemy.engine.Engine - INFO - [raw sql] {}
2025-03-24 19:41:58,510 - sqlalchemy.engine.Engine - INFO - SELECT @@sql_mode
2025-03-24 19:41:58,510 - sqlalchemy.engine.Engine - INFO - [raw sql] {}
2025-03-24 19:41:58,511 - sqlalchemy.engine.Engine - INFO - SELECT @@lower_case_table_names
2025-03-24 19:41:58,511 - sqlalchemy.engine.Engine - INFO - [raw sql] {}
2025-03-24 19:41:58,511 - sqlalchemy.engine.Engine - INFO - BEGIN (implicit)
2025-03-24 19:41:58,512 - sqlalchemy.engine.Engine - INFO - DESCRIBE `movies`.`user`
2025-03-24 19:41:58,512 - sqlalchemy.engine.Engine - INFO - [raw sql] {}
2025-03-24 19:41:58,513 - sqlalchemy.engine.Engine - INFO - DESCRIBE `movies`.`movie`
2025-03-24 19:41:58,513 - sqlalchemy.engine.Engine - INFO - [raw sql] {}
2025-03-24 19:41:58,514 - sqlalchemy.engine.Engine - INFO - DESCRIBE `movies`.`comment`
2025-03-24 19:41:58,514 - sqlalchemy.engine.Engine - INFO - [raw sql] {}
2025-03-24 19:41:58,516 - sqlalchemy.engine.Engine - INFO - COMMIT
2025-03-24 19:41:59,043 - sqlalchemy.engine.Engine - INFO - BEGIN (implicit)
2025-03-24 19:41:59,045 - sqlalchemy.engine.Engine - INFO - INSERT INTO user (username, email, password) VALUES (%(username__0)s, %(email__0)s, %(password__0)s), (%(username__1)s, %(email__1)s, %(password__1)s), (%(username__2)s, %(email__2)s, %(password__2)s) RETURNING user.id, user.id AS id__1
2025-03-24 19:41:59,045 - sqlalchemy.engine.Engine - INFO - [generated in 0.00007s (insertmanyvalues) 1/1 (ordered)] {'username__0': 'Alice', 'password__0': '$2b$12$rUKiwmRvEfhTO0NmreYxF.M5Ubektef9Zblo9yZXUb/Ksljg99kVu', 'email__0': 'alice@example.com', 'username__1': 'Bob', 'password__1': '$2b$12$zevH5W82aDgESTQ/p72FUOj45/uMl4Anble5loFBFD44GmJOcflCy', 'email__1': 'bob@example.com', 'username__2': 'Charlie', 'password__2': '$2b$12$Ce/6Oq.F43MOIszhmADSEuXsec1x/FRc4Rme6rWDUeDZRfcBqkUNy', 'email__2': 'charlie@example.com'}
2025-03-24 19:41:59,046 - sqlalchemy.engine.Engine - INFO - COMMIT
2025-03-24 19:41:59,049 - sqlalchemy.engine.Engine - INFO - BEGIN (implicit)
2025-03-24 19:41:59,050 - sqlalchemy.engine.Engine - INFO - INSERT INTO movie (title, director, year, genre) VALUES (%(title__0)s, %(director__0)s, %(year__0)s, %(genre__0)s), (%(title__1)s, %(director__1)s, %(year__1)s, %(genre__1)s), (%(title__2)s, %(director__2)s, %(year__2)s, %(genre__2)s), (%(title__3)s, %(director__3)s, %(year__3)s, %(genre__3)s), (%(title__4)s, %(director__4)s, %(year__4)s, %(genre__4)s) RETURNING movie.id, movie.id AS id__1
2025-03-24 19:41:59,050 - sqlalchemy.engine.Engine - INFO - [generated in 0.00006s (insertmanyvalues) 1/1 (ordered)] {'genre__0': 'Sci-Fi', 'director__0': 'Christopher Nolan', 'year__0': 2010, 'title__0': 'Inception', 'genre__1': 'Sci-Fi', 'director__1': 'Lana Wachowski, Lilly Wachowski', 'year__1': 1999, 'title__1': 'The Matrix', 'genre__2': 'Sci-Fi', 'director__2': 'Christopher Nolan', 'year__2': 2014, 'title__2': 'Interstellar', 'genre__3': 'Drama', 'director__3': 'Francis Ford Coppola', 'year__3': 1972, 'title__3': 'The Godfather', 'genre__4': 'Crime', 'director__4': 'Quentin Tarantino', 'year__4': 1994, 'title__4': 'Pulp Fiction'}
2025-03-24 19:41:59,051 - sqlalchemy.engine.Engine - INFO - COMMIT
2025-03-24 19:41:59,052 - root - INFO - Base de datos inicializada correctamente
2025-03-24 19:45:52,494 - root - INFO - Aplicación terminando...
2025-03-24 19:45:53,553 - root - INFO - Creando tablas y datos iniciales...
2025-03-24 19:45:54,087 - root - INFO - Base de datos inicializada correctamente
2025-03-24 19:46:27,351 - root - INFO - Aplicación terminando...
2025-03-24 19:46:28,200 - root - INFO - Creando tablas y datos iniciales...
2025-03-24 19:46:28,732 - root - INFO - Base de datos inicializada correctamente
2025-03-24 19:46:48,072 - root - INFO - Aplicación terminando...
2025-03-24 19:46:48,932 - root - INFO - Creando tablas y datos iniciales...
2025-03-24 19:46:49,462 - root - INFO - Base de datos inicializada correctamente
2025-03-24 19:47:05,697 - root - INFO - Aplicación terminando...
2025-03-24 19:47:10,706 - root - INFO - Creando tablas y datos iniciales...
2025-03-24 19:47:11,236 - root - INFO - Base de datos inicializada correctamente
2025-03-24 19:48:05,029 - root - INFO - Received prediction request for text: Me ha gustado
2025-03-24 19:48:05,029 - root - WARNING - Model not loaded, returning random prediction: positive
2025-03-24 20:51:35,359 - root - INFO - Creando tablas y datos iniciales...
2025-03-24 20:51:35,895 - root - INFO - Base de datos inicializada correctamente
2025-03-24 20:52:38,374 - root - ERROR - Exception calling inference service: HTTPConnectionPool(host='inference_service', port=8001): Max retries exceeded with url: /predict (Caused by NameResolutionError("<urllib3.connection.HTTPConnection object at 0x7f62c3978b90>: Failed to resolve 'inference_service' ([Errno -2] Name or service not known)"))
2025-03-24 21:36:16,159 - root - INFO - Aplicación terminando...
2025-03-24 21:40:14,342 - root - INFO - Creando tablas y datos iniciales...
2025-03-24 21:40:14,873 - root - INFO - Base de datos inicializada correctamente
2025-03-24 21:42:45,718 - root - INFO - Creando tablas y datos iniciales...
2025-03-24 21:42:46,261 - root - INFO - Base de datos inicializada correctamente
2025-03-24 21:42:50,122 - root - ERROR - Failed to initialize model: Could not load model distilbert-base-uncased-finetuned-sst-2-english with any of the following classes: (<class 'transformers.models.auto.modeling_auto.AutoModelForSequenceClassification'>,). See the original errors:

while loading with AutoModelForSequenceClassification, an error is thrown:
Traceback (most recent call last):
  File "/usr/local/lib/python3.12/site-packages/urllib3/connectionpool.py", line 464, in _make_request
    self._validate_conn(conn)
  File "/usr/local/lib/python3.12/site-packages/urllib3/connectionpool.py", line 1093, in _validate_conn
    conn.connect()
  File "/usr/local/lib/python3.12/site-packages/urllib3/connection.py", line 741, in connect
    sock_and_verified = _ssl_wrap_socket_and_match_hostname(
                        ^^^^^^^^^^^^^^^^^^^^^^^^^^^^^^^^^^^^
  File "/usr/local/lib/python3.12/site-packages/urllib3/connection.py", line 920, in _ssl_wrap_socket_and_match_hostname
    ssl_sock = ssl_wrap_socket(
               ^^^^^^^^^^^^^^^^
  File "/usr/local/lib/python3.12/site-packages/urllib3/util/ssl_.py", line 460, in ssl_wrap_socket
    ssl_sock = _ssl_wrap_socket_impl(sock, context, tls_in_tls, server_hostname)
               ^^^^^^^^^^^^^^^^^^^^^^^^^^^^^^^^^^^^^^^^^^^^^^^^^^^^^^^^^^^^^^^^^
  File "/usr/local/lib/python3.12/site-packages/urllib3/util/ssl_.py", line 504, in _ssl_wrap_socket_impl
    return ssl_context.wrap_socket(sock, server_hostname=server_hostname)
           ^^^^^^^^^^^^^^^^^^^^^^^^^^^^^^^^^^^^^^^^^^^^^^^^^^^^^^^^^^^^^^
  File "/usr/local/lib/python3.12/ssl.py", line 455, in wrap_socket
    return self.sslsocket_class._create(
           ^^^^^^^^^^^^^^^^^^^^^^^^^^^^^
  File "/usr/local/lib/python3.12/ssl.py", line 1041, in _create
    self.do_handshake()
  File "/usr/local/lib/python3.12/ssl.py", line 1319, in do_handshake
    self._sslobj.do_handshake()
ssl.SSLError: [SSL: WRONG_VERSION_NUMBER] wrong version number (_ssl.c:1010)

During handling of the above exception, another exception occurred:

Traceback (most recent call last):
  File "/usr/local/lib/python3.12/site-packages/urllib3/connectionpool.py", line 787, in urlopen
    response = self._make_request(
               ^^^^^^^^^^^^^^^^^^^
  File "/usr/local/lib/python3.12/site-packages/urllib3/connectionpool.py", line 488, in _make_request
    raise new_e
urllib3.exceptions.SSLError: [SSL: WRONG_VERSION_NUMBER] wrong version number (_ssl.c:1010)

The above exception was the direct cause of the following exception:

Traceback (most recent call last):
  File "/usr/local/lib/python3.12/site-packages/requests/adapters.py", line 667, in send
    resp = conn.urlopen(
           ^^^^^^^^^^^^^
  File "/usr/local/lib/python3.12/site-packages/urllib3/connectionpool.py", line 841, in urlopen
    retries = retries.increment(
              ^^^^^^^^^^^^^^^^^^
  File "/usr/local/lib/python3.12/site-packages/urllib3/util/retry.py", line 519, in increment
    raise MaxRetryError(_pool, url, reason) from reason  # type: ignore[arg-type]
    ^^^^^^^^^^^^^^^^^^^^^^^^^^^^^^^^^^^^^^^^^^^^^^^^^^^
urllib3.exceptions.MaxRetryError: HTTPSConnectionPool(host='huggingface.co', port=443): Max retries exceeded with url: /distilbert-base-uncased-finetuned-sst-2-english/resolve/main/tf_model.h5 (Caused by SSLError(SSLError(1, '[SSL: WRONG_VERSION_NUMBER] wrong version number (_ssl.c:1010)')))

During handling of the above exception, another exception occurred:

Traceback (most recent call last):
  File "/usr/local/lib/python3.12/site-packages/transformers/pipelines/base.py", line 291, in infer_framework_load_model
    model = model_class.from_pretrained(model, **kwargs)
            ^^^^^^^^^^^^^^^^^^^^^^^^^^^^^^^^^^^^^^^^^^^^
  File "/usr/local/lib/python3.12/site-packages/transformers/models/auto/auto_factory.py", line 573, in from_pretrained
    return model_class.from_pretrained(
           ^^^^^^^^^^^^^^^^^^^^^^^^^^^^
  File "/usr/local/lib/python3.12/site-packages/transformers/modeling_utils.py", line 272, in _wrapper
    return func(*args, **kwargs)
           ^^^^^^^^^^^^^^^^^^^^^
  File "/usr/local/lib/python3.12/site-packages/transformers/modeling_utils.py", line 4317, in from_pretrained
    checkpoint_files, sharded_metadata = _get_resolved_checkpoint_files(
                                         ^^^^^^^^^^^^^^^^^^^^^^^^^^^^^^^
  File "/usr/local/lib/python3.12/site-packages/transformers/modeling_utils.py", line 1109, in _get_resolved_checkpoint_files
    if has_file(pretrained_model_name_or_path, TF2_WEIGHTS_NAME, **has_file_kwargs):
       ^^^^^^^^^^^^^^^^^^^^^^^^^^^^^^^^^^^^^^^^^^^^^^^^^^^^^^^^^^^^^^^^^^^^^^^^^^^^
  File "/usr/local/lib/python3.12/site-packages/transformers/utils/hub.py", line 686, in has_file
    response = get_session().head(
               ^^^^^^^^^^^^^^^^^^^
  File "/usr/local/lib/python3.12/site-packages/requests/sessions.py", line 624, in head
    return self.request("HEAD", url, **kwargs)
           ^^^^^^^^^^^^^^^^^^^^^^^^^^^^^^^^^^^
  File "/usr/local/lib/python3.12/site-packages/requests/sessions.py", line 589, in request
    resp = self.send(prep, **send_kwargs)
           ^^^^^^^^^^^^^^^^^^^^^^^^^^^^^^
  File "/usr/local/lib/python3.12/site-packages/requests/sessions.py", line 703, in send
    r = adapter.send(request, **kwargs)
        ^^^^^^^^^^^^^^^^^^^^^^^^^^^^^^^
  File "/usr/local/lib/python3.12/site-packages/huggingface_hub/utils/_http.py", line 96, in send
    return super().send(request, *args, **kwargs)
           ^^^^^^^^^^^^^^^^^^^^^^^^^^^^^^^^^^^^^^
  File "/usr/local/lib/python3.12/site-packages/requests/adapters.py", line 698, in send
    raise SSLError(e, request=request)
requests.exceptions.SSLError: (MaxRetryError("HTTPSConnectionPool(host='huggingface.co', port=443): Max retries exceeded with url: /distilbert-base-uncased-finetuned-sst-2-english/resolve/main/tf_model.h5 (Caused by SSLError(SSLError(1, '[SSL: WRONG_VERSION_NUMBER] wrong version number (_ssl.c:1010)')))"), '(Request ID: f9daff26-7986-4e24-810b-5237a8fce8bd)')



2025-03-24 21:49:29,842 - root - INFO - Aplicación terminando...
2025-03-24 21:49:30,864 - root - INFO - Creando tablas y datos iniciales...
2025-03-24 21:49:31,397 - root - INFO - Base de datos inicializada correctamente
2025-03-24 21:54:12,536 - root - INFO - Aplicación terminando...
2025-03-24 21:54:13,437 - root - INFO - Creando tablas y datos iniciales...
2025-03-24 21:54:13,969 - root - INFO - Base de datos inicializada correctamente
2025-03-24 21:54:14,170 - root - INFO - Aplicación terminando...
2025-03-24 21:54:14,976 - root - INFO - Creando tablas y datos iniciales...
2025-03-24 21:54:15,506 - root - INFO - Base de datos inicializada correctamente
2025-03-24 21:54:17,010 - root - INFO - Aplicación terminando...
2025-03-24 21:54:17,886 - root - INFO - Creando tablas y datos iniciales...
2025-03-24 21:54:18,416 - root - INFO - Base de datos inicializada correctamente
2025-03-24 21:55:11,623 - root - INFO - Aplicación terminando...
2025-03-24 21:55:12,523 - root - INFO - Creando tablas y datos iniciales...
2025-03-24 21:55:13,064 - root - INFO - Base de datos inicializada correctamente
2025-03-24 21:59:02,408 - root - INFO - Aplicación terminando...
2025-03-24 21:59:03,276 - root - INFO - Creando tablas y datos iniciales...
2025-03-24 21:59:03,806 - root - INFO - Base de datos inicializada correctamente
2025-03-24 21:59:51,897 - root - INFO - Aplicación terminando...
2025-03-24 21:59:53,781 - root - INFO - Creando tablas y datos iniciales...
2025-03-24 21:59:54,312 - root - INFO - Base de datos inicializada correctamente
2025-03-24 21:59:54,514 - root - INFO - Aplicación terminando...
2025-03-24 22:00:04,572 - root - INFO - Creando tablas y datos iniciales...
2025-03-24 22:00:05,103 - root - INFO - Base de datos inicializada correctamente
2025-03-24 22:00:39,171 - root - INFO - Aplicación terminando...
2025-03-24 22:00:41,739 - root - INFO - Creando tablas y datos iniciales...
2025-03-24 22:00:42,274 - root - INFO - Base de datos inicializada correctamente
2025-03-24 22:00:42,977 - root - INFO - Aplicación terminando...
2025-03-24 22:00:43,846 - root - INFO - Creando tablas y datos iniciales...
2025-03-24 22:00:44,377 - root - INFO - Base de datos inicializada correctamente
2025-03-24 22:00:45,580 - root - INFO - Aplicación terminando...
2025-03-24 22:00:57,121 - root - INFO - Creando tablas y datos iniciales...
2025-03-24 22:00:57,659 - root - INFO - Base de datos inicializada correctamente
2025-03-24 22:00:59,965 - root - INFO - Aplicación terminando...
2025-03-24 22:01:00,875 - root - INFO - Creando tablas y datos iniciales...
2025-03-24 22:01:01,413 - root - INFO - Base de datos inicializada correctamente
2025-03-24 22:01:39,185 - root - INFO - Aplicación terminando...
2025-03-24 22:01:40,084 - root - INFO - Creando tablas y datos iniciales...
2025-03-24 22:01:40,624 - root - INFO - Base de datos inicializada correctamente
2025-03-24 22:01:51,346 - root - INFO - Aplicación terminando...
2025-03-24 22:01:52,353 - root - INFO - Creando tablas y datos iniciales...
2025-03-24 22:01:52,890 - root - INFO - Base de datos inicializada correctamente
2025-03-24 22:01:53,893 - root - INFO - Aplicación terminando...
2025-03-24 22:01:54,772 - root - INFO - Creando tablas y datos iniciales...
2025-03-24 22:01:55,306 - root - INFO - Base de datos inicializada correctamente
2025-03-24 22:01:55,507 - root - INFO - Aplicación terminando...
2025-03-24 22:01:57,707 - root - INFO - Creando tablas y datos iniciales...
2025-03-24 22:01:58,238 - root - INFO - Base de datos inicializada correctamente
2025-03-24 22:03:42,837 - root - INFO - Aplicación terminando...
2025-03-24 22:03:54,647 - root - INFO - Creando tablas y datos iniciales...
2025-03-24 22:03:55,182 - root - INFO - Base de datos inicializada correctamente
2025-03-24 22:04:06,105 - root - INFO - Aplicación terminando...
2025-03-24 22:04:06,998 - root - INFO - Creando tablas y datos iniciales...
2025-03-24 22:04:07,537 - root - INFO - Base de datos inicializada correctamente
2025-03-24 22:05:10,658 - root - INFO - Aplicación terminando...
2025-03-24 22:05:11,772 - root - INFO - Creando tablas y datos iniciales...
2025-03-24 22:05:12,313 - root - INFO - Base de datos inicializada correctamente
2025-03-24 22:05:12,514 - root - INFO - Aplicación terminando...
2025-03-24 22:05:15,764 - root - INFO - Creando tablas y datos iniciales...
2025-03-24 22:05:16,293 - root - INFO - Base de datos inicializada correctamente
2025-03-24 22:05:19,000 - root - INFO - Aplicación terminando...
2025-03-24 22:07:57,756 - root - INFO - Creando tablas y datos iniciales...
2025-03-24 22:07:58,291 - root - INFO - Base de datos inicializada correctamente
2025-03-24 22:10:11,443 - root - INFO - Aplicación terminando...
2025-03-24 22:10:12,364 - root - INFO - Creando tablas y datos iniciales...
2025-03-24 22:10:12,898 - root - INFO - Base de datos inicializada correctamente
2025-03-24 23:10:30,351 - httpx - INFO - HTTP Request: POST http://testserver/movies/3/comments "HTTP/1.1 201 Created"
2025-03-24 23:10:30,360 - httpx - INFO - HTTP Request: POST http://testserver/movies/1/comments "HTTP/1.1 422 Unprocessable Entity"
2025-03-24 23:10:30,362 - httpx - INFO - HTTP Request: POST http://testserver/movies/1/comments "HTTP/1.1 422 Unprocessable Entity"
2025-03-24 23:10:30,364 - httpx - INFO - HTTP Request: POST http://testserver/movies/1/comments "HTTP/1.1 422 Unprocessable Entity"
2025-03-24 23:10:30,371 - httpx - INFO - HTTP Request: POST http://testserver/movies/4/comments "HTTP/1.1 404 Not Found"
2025-03-24 23:10:30,379 - httpx - INFO - HTTP Request: POST http://testserver/movies/1/comments "HTTP/1.1 404 Not Found"
2025-03-24 23:10:30,389 - httpx - INFO - HTTP Request: DELETE http://testserver/movies/1 "HTTP/1.1 200 OK"
2025-03-24 23:10:30,398 - httpx - INFO - HTTP Request: GET http://testserver/movies/1/comments "HTTP/1.1 200 OK"
2025-03-24 23:10:30,405 - httpx - INFO - HTTP Request: GET http://testserver/movies/3/comments "HTTP/1.1 200 OK"
2025-03-24 23:10:30,412 - httpx - INFO - HTTP Request: GET http://testserver/movies/4/comments "HTTP/1.1 404 Not Found"
2025-03-24 23:10:30,420 - httpx - INFO - HTTP Request: GET http://testserver/users/2/comments "HTTP/1.1 200 OK"
2025-03-24 23:10:30,427 - httpx - INFO - HTTP Request: GET http://testserver/users/3/comments "HTTP/1.1 200 OK"
2025-03-24 23:10:30,434 - httpx - INFO - HTTP Request: GET http://testserver/users/4/comments "HTTP/1.1 404 Not Found"
2025-03-24 23:10:30,440 - httpx - INFO - HTTP Request: POST http://testserver/movies "HTTP/1.1 201 Created"
2025-03-24 23:10:30,448 - httpx - INFO - HTTP Request: POST http://testserver/movies "HTTP/1.1 422 Unprocessable Entity"
2025-03-24 23:10:30,450 - httpx - INFO - HTTP Request: POST http://testserver/movies "HTTP/1.1 422 Unprocessable Entity"
2025-03-24 23:10:30,452 - httpx - INFO - HTTP Request: POST http://testserver/movies "HTTP/1.1 422 Unprocessable Entity"
2025-03-24 23:10:30,454 - httpx - INFO - HTTP Request: POST http://testserver/movies "HTTP/1.1 422 Unprocessable Entity"
2025-03-24 23:10:30,461 - httpx - INFO - HTTP Request: DELETE http://testserver/movies/1 "HTTP/1.1 200 OK"
2025-03-24 23:10:30,466 - httpx - INFO - HTTP Request: DELETE http://testserver/movies/4 "HTTP/1.1 404 Not Found"
2025-03-24 23:10:30,471 - httpx - INFO - HTTP Request: GET http://testserver/movies/1 "HTTP/1.1 200 OK"
2025-03-24 23:10:30,476 - httpx - INFO - HTTP Request: GET http://testserver/movies/4 "HTTP/1.1 404 Not Found"
2025-03-24 23:10:30,481 - httpx - INFO - HTTP Request: GET http://testserver/movies "HTTP/1.1 200 OK"
2025-03-24 23:10:30,485 - httpx - INFO - HTTP Request: GET http://testserver/movies "HTTP/1.1 200 OK"
2025-03-24 23:10:30,491 - httpx - INFO - HTTP Request: GET http://testserver/movies/search?title=cept "HTTP/1.1 200 OK"
2025-03-24 23:10:30,496 - httpx - INFO - HTTP Request: GET http://testserver/movies/search?title=Tenet "HTTP/1.1 200 OK"
2025-03-24 23:10:30,501 - httpx - INFO - HTTP Request: GET http://testserver/users/1 "HTTP/1.1 200 OK"
2025-03-24 23:10:30,506 - httpx - INFO - HTTP Request: GET http://testserver/users/4 "HTTP/1.1 404 Not Found"
2025-03-24 23:10:30,512 - httpx - INFO - HTTP Request: GET http://testserver/users "HTTP/1.1 200 OK"
2025-03-24 23:10:30,516 - httpx - INFO - HTTP Request: GET http://testserver/users "HTTP/1.1 200 OK"
2025-03-24 22:11:28,550 - root - INFO - Aplicación terminando...
2025-03-24 22:11:29,427 - root - INFO - Creando tablas y datos iniciales...
2025-03-24 22:11:29,961 - root - INFO - Base de datos inicializada correctamente
2025-03-24 22:11:31,767 - root - INFO - Aplicación terminando...
2025-03-24 22:11:32,653 - root - INFO - Creando tablas y datos iniciales...
2025-03-24 22:11:33,195 - root - INFO - Base de datos inicializada correctamente
2025-03-24 22:11:33,697 - root - INFO - Aplicación terminando...
2025-03-24 22:11:34,551 - root - INFO - Creando tablas y datos iniciales...
2025-03-24 22:11:35,089 - root - INFO - Base de datos inicializada correctamente
2025-03-24 22:14:53,860 - root - INFO - Creando tablas y datos iniciales...
2025-03-24 22:14:54,394 - root - INFO - Base de datos inicializada correctamente
2025-03-24 22:18:24,540 - root - ERROR - Exception calling inference service: HTTPConnectionPool(host='inference_service', port=8001): Max retries exceeded with url: /predict (Caused by NameResolutionError("<urllib3.connection.HTTPConnection object at 0x7fd502e88260>: Failed to resolve 'inference_service' ([Errno -2] Name or service not known)"))
2025-03-24 22:21:57,981 - root - INFO - Aplicación terminando...
2025-03-24 22:22:12,655 - root - INFO - Creando tablas y datos iniciales...
2025-03-24 22:22:13,190 - root - INFO - Base de datos inicializada correctamente
2025-03-24 22:22:14,997 - root - ERROR - Failed to initialize model: Could not load model distilbert-base-uncased-finetuned-sst-2-english with any of the following classes: (<class 'transformers.models.auto.modeling_auto.AutoModelForSequenceClassification'>,). See the original errors:

while loading with AutoModelForSequenceClassification, an error is thrown:
Traceback (most recent call last):
  File "/usr/local/lib/python3.12/site-packages/urllib3/connectionpool.py", line 464, in _make_request
    self._validate_conn(conn)
  File "/usr/local/lib/python3.12/site-packages/urllib3/connectionpool.py", line 1093, in _validate_conn
    conn.connect()
  File "/usr/local/lib/python3.12/site-packages/urllib3/connection.py", line 741, in connect
    sock_and_verified = _ssl_wrap_socket_and_match_hostname(
                        ^^^^^^^^^^^^^^^^^^^^^^^^^^^^^^^^^^^^
  File "/usr/local/lib/python3.12/site-packages/urllib3/connection.py", line 920, in _ssl_wrap_socket_and_match_hostname
    ssl_sock = ssl_wrap_socket(
               ^^^^^^^^^^^^^^^^
  File "/usr/local/lib/python3.12/site-packages/urllib3/util/ssl_.py", line 460, in ssl_wrap_socket
    ssl_sock = _ssl_wrap_socket_impl(sock, context, tls_in_tls, server_hostname)
               ^^^^^^^^^^^^^^^^^^^^^^^^^^^^^^^^^^^^^^^^^^^^^^^^^^^^^^^^^^^^^^^^^
  File "/usr/local/lib/python3.12/site-packages/urllib3/util/ssl_.py", line 504, in _ssl_wrap_socket_impl
    return ssl_context.wrap_socket(sock, server_hostname=server_hostname)
           ^^^^^^^^^^^^^^^^^^^^^^^^^^^^^^^^^^^^^^^^^^^^^^^^^^^^^^^^^^^^^^
  File "/usr/local/lib/python3.12/ssl.py", line 455, in wrap_socket
    return self.sslsocket_class._create(
           ^^^^^^^^^^^^^^^^^^^^^^^^^^^^^
  File "/usr/local/lib/python3.12/ssl.py", line 1041, in _create
    self.do_handshake()
  File "/usr/local/lib/python3.12/ssl.py", line 1319, in do_handshake
    self._sslobj.do_handshake()
ssl.SSLError: [SSL: WRONG_VERSION_NUMBER] wrong version number (_ssl.c:1010)

During handling of the above exception, another exception occurred:

Traceback (most recent call last):
  File "/usr/local/lib/python3.12/site-packages/urllib3/connectionpool.py", line 787, in urlopen
    response = self._make_request(
               ^^^^^^^^^^^^^^^^^^^
  File "/usr/local/lib/python3.12/site-packages/urllib3/connectionpool.py", line 488, in _make_request
    raise new_e
urllib3.exceptions.SSLError: [SSL: WRONG_VERSION_NUMBER] wrong version number (_ssl.c:1010)

The above exception was the direct cause of the following exception:

Traceback (most recent call last):
  File "/usr/local/lib/python3.12/site-packages/requests/adapters.py", line 667, in send
    resp = conn.urlopen(
           ^^^^^^^^^^^^^
  File "/usr/local/lib/python3.12/site-packages/urllib3/connectionpool.py", line 841, in urlopen
    retries = retries.increment(
              ^^^^^^^^^^^^^^^^^^
  File "/usr/local/lib/python3.12/site-packages/urllib3/util/retry.py", line 519, in increment
    raise MaxRetryError(_pool, url, reason) from reason  # type: ignore[arg-type]
    ^^^^^^^^^^^^^^^^^^^^^^^^^^^^^^^^^^^^^^^^^^^^^^^^^^^
urllib3.exceptions.MaxRetryError: HTTPSConnectionPool(host='huggingface.co', port=443): Max retries exceeded with url: /distilbert-base-uncased-finetuned-sst-2-english/resolve/main/tf_model.h5 (Caused by SSLError(SSLError(1, '[SSL: WRONG_VERSION_NUMBER] wrong version number (_ssl.c:1010)')))

During handling of the above exception, another exception occurred:

Traceback (most recent call last):
  File "/usr/local/lib/python3.12/site-packages/transformers/pipelines/base.py", line 291, in infer_framework_load_model
    model = model_class.from_pretrained(model, **kwargs)
            ^^^^^^^^^^^^^^^^^^^^^^^^^^^^^^^^^^^^^^^^^^^^
  File "/usr/local/lib/python3.12/site-packages/transformers/models/auto/auto_factory.py", line 573, in from_pretrained
    return model_class.from_pretrained(
           ^^^^^^^^^^^^^^^^^^^^^^^^^^^^
  File "/usr/local/lib/python3.12/site-packages/transformers/modeling_utils.py", line 272, in _wrapper
    return func(*args, **kwargs)
           ^^^^^^^^^^^^^^^^^^^^^
  File "/usr/local/lib/python3.12/site-packages/transformers/modeling_utils.py", line 4317, in from_pretrained
    checkpoint_files, sharded_metadata = _get_resolved_checkpoint_files(
                                         ^^^^^^^^^^^^^^^^^^^^^^^^^^^^^^^
  File "/usr/local/lib/python3.12/site-packages/transformers/modeling_utils.py", line 1109, in _get_resolved_checkpoint_files
    if has_file(pretrained_model_name_or_path, TF2_WEIGHTS_NAME, **has_file_kwargs):
       ^^^^^^^^^^^^^^^^^^^^^^^^^^^^^^^^^^^^^^^^^^^^^^^^^^^^^^^^^^^^^^^^^^^^^^^^^^^^
  File "/usr/local/lib/python3.12/site-packages/transformers/utils/hub.py", line 686, in has_file
    response = get_session().head(
               ^^^^^^^^^^^^^^^^^^^
  File "/usr/local/lib/python3.12/site-packages/requests/sessions.py", line 624, in head
    return self.request("HEAD", url, **kwargs)
           ^^^^^^^^^^^^^^^^^^^^^^^^^^^^^^^^^^^
  File "/usr/local/lib/python3.12/site-packages/requests/sessions.py", line 589, in request
    resp = self.send(prep, **send_kwargs)
           ^^^^^^^^^^^^^^^^^^^^^^^^^^^^^^
  File "/usr/local/lib/python3.12/site-packages/requests/sessions.py", line 703, in send
    r = adapter.send(request, **kwargs)
        ^^^^^^^^^^^^^^^^^^^^^^^^^^^^^^^
  File "/usr/local/lib/python3.12/site-packages/huggingface_hub/utils/_http.py", line 96, in send
    return super().send(request, *args, **kwargs)
           ^^^^^^^^^^^^^^^^^^^^^^^^^^^^^^^^^^^^^^
  File "/usr/local/lib/python3.12/site-packages/requests/adapters.py", line 698, in send
    raise SSLError(e, request=request)
requests.exceptions.SSLError: (MaxRetryError("HTTPSConnectionPool(host='huggingface.co', port=443): Max retries exceeded with url: /distilbert-base-uncased-finetuned-sst-2-english/resolve/main/tf_model.h5 (Caused by SSLError(SSLError(1, '[SSL: WRONG_VERSION_NUMBER] wrong version number (_ssl.c:1010)')))"), '(Request ID: 5f21115e-ac0b-4fc9-9392-c3fdbc4a0def)')



2025-03-24 22:24:35,713 - root - INFO - Received prediction request for text: Me ha gustado
2025-03-24 22:24:35,714 - root - WARNING - Model not loaded, returning random prediction: negative
2025-03-24 22:29:07,955 - root - INFO - Aplicación terminando...
2025-03-25 09:49:55,431 - root - INFO - Creando tablas y datos iniciales...
2025-03-25 09:49:55,970 - root - INFO - Base de datos inicializada correctamente
2025-03-25 09:49:57,923 - root - ERROR - Failed to initialize model: Could not load model distilbert-base-uncased-finetuned-sst-2-english with any of the following classes: (<class 'transformers.models.auto.modeling_auto.AutoModelForSequenceClassification'>,). See the original errors:

while loading with AutoModelForSequenceClassification, an error is thrown:
Traceback (most recent call last):
  File "/usr/local/lib/python3.12/site-packages/urllib3/connectionpool.py", line 464, in _make_request
    self._validate_conn(conn)
  File "/usr/local/lib/python3.12/site-packages/urllib3/connectionpool.py", line 1093, in _validate_conn
    conn.connect()
  File "/usr/local/lib/python3.12/site-packages/urllib3/connection.py", line 741, in connect
    sock_and_verified = _ssl_wrap_socket_and_match_hostname(
                        ^^^^^^^^^^^^^^^^^^^^^^^^^^^^^^^^^^^^
  File "/usr/local/lib/python3.12/site-packages/urllib3/connection.py", line 920, in _ssl_wrap_socket_and_match_hostname
    ssl_sock = ssl_wrap_socket(
               ^^^^^^^^^^^^^^^^
  File "/usr/local/lib/python3.12/site-packages/urllib3/util/ssl_.py", line 460, in ssl_wrap_socket
    ssl_sock = _ssl_wrap_socket_impl(sock, context, tls_in_tls, server_hostname)
               ^^^^^^^^^^^^^^^^^^^^^^^^^^^^^^^^^^^^^^^^^^^^^^^^^^^^^^^^^^^^^^^^^
  File "/usr/local/lib/python3.12/site-packages/urllib3/util/ssl_.py", line 504, in _ssl_wrap_socket_impl
    return ssl_context.wrap_socket(sock, server_hostname=server_hostname)
           ^^^^^^^^^^^^^^^^^^^^^^^^^^^^^^^^^^^^^^^^^^^^^^^^^^^^^^^^^^^^^^
  File "/usr/local/lib/python3.12/ssl.py", line 455, in wrap_socket
    return self.sslsocket_class._create(
           ^^^^^^^^^^^^^^^^^^^^^^^^^^^^^
  File "/usr/local/lib/python3.12/ssl.py", line 1041, in _create
    self.do_handshake()
  File "/usr/local/lib/python3.12/ssl.py", line 1319, in do_handshake
    self._sslobj.do_handshake()
ssl.SSLError: [SSL: WRONG_VERSION_NUMBER] wrong version number (_ssl.c:1010)

During handling of the above exception, another exception occurred:

Traceback (most recent call last):
  File "/usr/local/lib/python3.12/site-packages/urllib3/connectionpool.py", line 787, in urlopen
    response = self._make_request(
               ^^^^^^^^^^^^^^^^^^^
  File "/usr/local/lib/python3.12/site-packages/urllib3/connectionpool.py", line 488, in _make_request
    raise new_e
urllib3.exceptions.SSLError: [SSL: WRONG_VERSION_NUMBER] wrong version number (_ssl.c:1010)

The above exception was the direct cause of the following exception:

Traceback (most recent call last):
  File "/usr/local/lib/python3.12/site-packages/requests/adapters.py", line 667, in send
    resp = conn.urlopen(
           ^^^^^^^^^^^^^
  File "/usr/local/lib/python3.12/site-packages/urllib3/connectionpool.py", line 841, in urlopen
    retries = retries.increment(
              ^^^^^^^^^^^^^^^^^^
  File "/usr/local/lib/python3.12/site-packages/urllib3/util/retry.py", line 519, in increment
    raise MaxRetryError(_pool, url, reason) from reason  # type: ignore[arg-type]
    ^^^^^^^^^^^^^^^^^^^^^^^^^^^^^^^^^^^^^^^^^^^^^^^^^^^
urllib3.exceptions.MaxRetryError: HTTPSConnectionPool(host='huggingface.co', port=443): Max retries exceeded with url: /distilbert-base-uncased-finetuned-sst-2-english/resolve/main/tf_model.h5 (Caused by SSLError(SSLError(1, '[SSL: WRONG_VERSION_NUMBER] wrong version number (_ssl.c:1010)')))

During handling of the above exception, another exception occurred:

Traceback (most recent call last):
  File "/usr/local/lib/python3.12/site-packages/transformers/pipelines/base.py", line 291, in infer_framework_load_model
    model = model_class.from_pretrained(model, **kwargs)
            ^^^^^^^^^^^^^^^^^^^^^^^^^^^^^^^^^^^^^^^^^^^^
  File "/usr/local/lib/python3.12/site-packages/transformers/models/auto/auto_factory.py", line 573, in from_pretrained
    return model_class.from_pretrained(
           ^^^^^^^^^^^^^^^^^^^^^^^^^^^^
  File "/usr/local/lib/python3.12/site-packages/transformers/modeling_utils.py", line 272, in _wrapper
    return func(*args, **kwargs)
           ^^^^^^^^^^^^^^^^^^^^^
  File "/usr/local/lib/python3.12/site-packages/transformers/modeling_utils.py", line 4317, in from_pretrained
    checkpoint_files, sharded_metadata = _get_resolved_checkpoint_files(
                                         ^^^^^^^^^^^^^^^^^^^^^^^^^^^^^^^
  File "/usr/local/lib/python3.12/site-packages/transformers/modeling_utils.py", line 1109, in _get_resolved_checkpoint_files
    if has_file(pretrained_model_name_or_path, TF2_WEIGHTS_NAME, **has_file_kwargs):
       ^^^^^^^^^^^^^^^^^^^^^^^^^^^^^^^^^^^^^^^^^^^^^^^^^^^^^^^^^^^^^^^^^^^^^^^^^^^^
  File "/usr/local/lib/python3.12/site-packages/transformers/utils/hub.py", line 686, in has_file
    response = get_session().head(
               ^^^^^^^^^^^^^^^^^^^
  File "/usr/local/lib/python3.12/site-packages/requests/sessions.py", line 624, in head
    return self.request("HEAD", url, **kwargs)
           ^^^^^^^^^^^^^^^^^^^^^^^^^^^^^^^^^^^
  File "/usr/local/lib/python3.12/site-packages/requests/sessions.py", line 589, in request
    resp = self.send(prep, **send_kwargs)
           ^^^^^^^^^^^^^^^^^^^^^^^^^^^^^^
  File "/usr/local/lib/python3.12/site-packages/requests/sessions.py", line 703, in send
    r = adapter.send(request, **kwargs)
        ^^^^^^^^^^^^^^^^^^^^^^^^^^^^^^^
  File "/usr/local/lib/python3.12/site-packages/huggingface_hub/utils/_http.py", line 96, in send
    return super().send(request, *args, **kwargs)
           ^^^^^^^^^^^^^^^^^^^^^^^^^^^^^^^^^^^^^^
  File "/usr/local/lib/python3.12/site-packages/requests/adapters.py", line 698, in send
    raise SSLError(e, request=request)
requests.exceptions.SSLError: (MaxRetryError("HTTPSConnectionPool(host='huggingface.co', port=443): Max retries exceeded with url: /distilbert-base-uncased-finetuned-sst-2-english/resolve/main/tf_model.h5 (Caused by SSLError(SSLError(1, '[SSL: WRONG_VERSION_NUMBER] wrong version number (_ssl.c:1010)')))"), '(Request ID: e98e77a0-dec7-476d-8cc3-0b9d3e65e990)')



